Workbook

Sheet TAV 1
M1: KUR/PPB/FO-002
M2: Rev. 03 / 25 Juli 2025
A3: DAFTAR HADIR SISWA
A4: ( CATATAN HARIAN GURU DAN DAFTAR NILAI )
A5: SMK MUHAMMADIYAH 1 BANTUL
A6: KELAS : X TAV / TE
A8: MATA PELAJARAN :.................................................. | L8: SEMESTER :..................
A9: GURU MATA PELAJARAN :.................................................. | L9: TAHUN PELAJARAN : 2025/2026
A10: WALI AMANAH | C10: : Hendrian Nugroho, S.Pd
A11: NOMOR | C11: NAMA | D11: BULAN : | I11: JUMLAH | L11: Nilai Tugas Harian | Q11: Nilai KD
A12: URUT | B12: INDUK | I12: S | J12: I | K12: A | L12: 1 | M12: 2 | N12: 3 | O12: 4 | P12: 5
A13: 1 | B13: 14375 | C13: ARIF YUSUF MAULANA
A14: 2 | B14: 14376 | C14: AZRIEL GALANG NURKHOLIS
A15: 3 | B15: 14377 | C15: BAYU AJI NUGROHO
A16: 4 | B16: 14378 | C16: MAULANA QOLBI
A17: 5 | B17: 14379 | C17: MERLIN PUTRI RAMADHANI
A18: 6 | B18: 14380 | C18: MUHAMMAD AKBAR
A19: 7 | B19: 14381 | C19: MUHAMMAD HASBY
A20: 8 | B20: 14382 | C20: NANDA BAGUS DWI FIRMANSYAH
A21: 9 | B21: 14383 | C21: NIZA NARENDRA KARUNIA GUSTI
A22: 10 | B22: 14384 | C22: RAIZ PANJI SAPUTRO
A23: 11 | B23: 14385 | C23: RAZAQA ADITYA FAZA
A24: 12 | B24: 14386 | C24: RIDWAN MAULANA
A25: 13 | B25: 14387 | C25: VANO PUTRA PERDANA WIJAYA
A26: 14
A27: 15
A28: 16
A29: 17
A30: 18
A31: 19
A32: 20
A34: CATATAN HARIAN GURU | L34: Deskripsi Penilaian
A35: NO | B35: Tanggal | C35: Kegiatan Pembelajaran | D35: Materi Pembelajaran
A36: 1 | C36: Menerangkan/Diskusi/Tugas/Ujian*) | L36: 1
A37: 2 | C37: Menerangkan/Diskusi/Tugas/Ujian*) | L37: 2
A38: 3 | C38: Menerangkan/Diskusi/Tugas/Ujian*) | L38: 3
A39: 4 | C39: Menerangkan/Diskusi/Tugas/Ujian*) | L39: 4
A40: 5 | C40: Menerangkan/Diskusi/Tugas/Ujian*) | L40: 5
A41: Keterangan : | K41: Bantul,……………………………………….
A42: Penilaian diisikan setiap kali melakukan penilaian harian berupa tugas, tes tertulis, tes lisan, tes unjuk kerja atau portopolio ( Validasi setiap Bulan ) | K42: Guru Bidang Studi
...

Sheet TPM 1
M1: KUR/PPB/FO-002
M2: Rev. 03 / 25 Juli 2025
A3: DAFTAR HADIR SISWA
A4: ( CATATAN HARIAN GURU DAN DAFTAR NILAI )
A5: SMK MUHAMMADIYAH 1 BANTUL
A6: KELAS : X TPM 1 / TM 1
A8: MATA PELAJARAN :.................................................. | L8: SEMESTER :..................
A9: GURU MATA PELAJARAN :.................................................. | L9: TAHUN PELAJARAN : 2025/2026
A10: WALI AMANAH | C10: : Listyo Budiarto, S.Pd
A11: NOMOR | C11: NAMA | D11: BULAN : | I11: JUMLAH | L11: Nilai Tugas Harian | Q11: Nilai KD
A12: URUT | B12: INDUK | I12: S | J12: I | K12: A | L12: 1 | M12: 2 | N12: 3 | O12: 4 | P12: 5
A13: 1 | B13: 14388 | C13: ADNAN AS SYIFA CANDRA WIBAWA
A14: 2 | B14: 14389 | C14: AHMAD AFIQ MAULANA
A15: 3 | B15: 14390 | C15: ALFAREL FRIDZI NAUVALADI
A16: 4 | B16: 14391 | C16: ASYRAF AULIA RAHMAN
A17: 5 | B17: 14392 | C17: ATHAR AL FATIH IBROHIM
A18: 6 | B18: 14393 | C18: BAGAS ARDHI PANGESTU
A19: 7 | B19: 14394 | C19: BINTANG RADITHYA JAVAS NARARYA
A20: 8 | B20: 14395 | C20: BIRLIANZA GAHZY ARVEL ARISQI
A21: 9 | B21: 14396 | C21: CAESAR GANENDRA DEVLIN
A22: 10 | B22: 14397 | C22: FADLI SYAIFUDIN ILHAM
A23: 11 | B23: 14398 | C23: FAJAR DWI NUGROHO
A24: 12 | B24: 14399 | C24: FAREL ADITYA PRATAMA
... A41: 29 | B41: 14417 | C41: WAHIDIN IRYANSYAH PUTRO
A42: 30
A43: 31
A44: 32
A45: 33
A46: 34
A47: 35
A48: 36
A50: CATATAN HARIAN GURU | L50: Deskripsi Penilaian
A51: NO | B51: Tanggal | C51: Kegiatan Pembelajaran | D51: Materi Pembelajaran
A52: 1 | C52: Menerangkan/Diskusi/Tugas/Ujian*) | L52: 1
A53: 2 | C53: Menerangkan/Diskusi/Tugas/Ujian*) | L53: 2
A54: 3 | C54: Menerangkan/Diskusi/Tugas/Ujian*) | L54: 3
A55: 4 | C55: Menerangkan/Diskusi/Tugas/Ujian*) | L55: 4
A56: 5 | C56: Menerangkan/Diskusi/Tugas/Ujian*) | L56: 5
A57: Keterangan : | K57: Bantul,……………………………………….
A58: Penilaian diisikan setiap kali melakukan penilaian harian berupa tugas, tes tertulis, tes lisan, tes unjuk kerja atau portopolio ( Validasi setiap Bulan ) | K58: Guru Bidang Studi
...

Sheet TPM 2
M1: KUR/PPB/FO-002
M2: Rev. 03 / 25 Juli 2025
A3: DAFTAR HADIR SISWA
A4: ( CATATAN HARIAN GURU DAN DAFTAR NILAI )
A5: SMK MUHAMMADIYAH 1 BANTUL
A6: KELAS : X TPM 2 / TM 2
A8: MATA PELAJARAN :.................................................. | L8: SEMESTER :..................
A9: GURU MATA PELAJARAN :.................................................. | L9: TAHUN PELAJARAN : 2025/2026
A10: WALI AMANAH | C10: : Frendino Ary P, S.Pd.Jas
A11: NOMOR | C11: NAMA | D11: BULAN : | I11: JUMLAH | L11: Nilai Tugas Harian | Q11: Nilai KD
A12: URUT | B12: INDUK | I12: S | J12: I | K12: A | L12: 1 | M12: 2 | N12: 3 | O12: 4 | P12: 5
A13: 1 | B13: 14418 | C13: ADHITYA PRATAMA
A14: 2 | B14: 14419 | C14: AFLAH AL TAQI
A15: 3 | B15: 14420 | C15: AGUSTYAN PUTRA YUASTINO
A16: 4 | B16: 14421 | C16: AKHMAD MALIK MUSTOFA
A17: 5 | B17: 14422 | C17: ALIF MAULIDAN
A18: 6 | B18: 14423 | C18: ANANDA RIFANO SAPUTRA
A19: 7 | B19: 14424 | C19: ANJAR RIZKI SAPUTRO
A20: 8 | B20: 14425 | C20: ASSEGAF AMANAH SLAMET RAHARJO
A21: 9 | B21: 14426 | C21: BAGUS SUDARMANTO
A22: 10 | B22: 14427 | C22: BIMO FAJAR KUSUMA
A23: 11 | B23: 14428 | C23: DIMAS BAGUS TRISULA
A24: 12 | B24: 14429 | C24: FAJAR HERMAWAN
... A42: 30 | B42: 14447 | C42: WAKHID CAHYA PERMANA
A43: 31
A44: 32
A45: 33
A46: 34
A47: 35
A48: 36
A50: CATATAN HARIAN GURU | L50: Deskripsi Penilaian
A51: NO | B51: Tanggal | C51: Kegiatan Pembelajaran | D51: Materi Pembelajaran
A52: 1 | C52: Menerangkan/Diskusi/Tugas/Ujian*) | L52: 1
A53: 2 | C53: Menerangkan/Diskusi/Tugas/Ujian*) | L53: 2
A54: 3 | C54: Menerangkan/Diskusi/Tugas/Ujian*) | L54: 3
A55: 4 | C55: Menerangkan/Diskusi/Tugas/Ujian*) | L55: 4
A56: 5 | C56: Menerangkan/Diskusi/Tugas/Ujian*) | L56: 5
A57: Keterangan : | K57: Bantul,……………………………………….
A58: Penilaian diisikan setiap kali melakukan penilaian harian berupa tugas, tes tertulis, tes lisan, tes unjuk kerja atau portopolio ( Validasi setiap Bulan ) | K58: Guru Bidang Studi
A60: *) Pada kolom kegiatan pembelajaran coret yang tidak dilakukan, kegiatan pembelajaran bisa lebih dari satu kegiatan
...

Sheet TKR 1
M1: KUR/PPB/FO-002
M2: Rev. 03 / 25 Juli 2025
A3: DAFTAR HADIR SISWA
A4: ( CATATAN HARIAN GURU DAN DAFTAR NILAI )
A5: SMK MUHAMMADIYAH 1 BANTUL
A6: KELAS : X TKR 1 / TO 1
A8: MATA PELAJARAN :.................................................. | L8: SEMESTER :..................
A9: GURU MATA PELAJARAN :.................................................. | L9: TAHUN PELAJARAN : 2025/2026
A10: WALI AMANAH | C10: : Tanindra Wijananto, S.Pd
A11: NOMOR | C11: NAMA | D11: BULAN : | I11: JUMLAH | L11: Nilai Tugas Harian | Q11: Nilai KD
A12: URUT | B12: INDUK | I12: S | J12: I | K12: A | L12: 1 | M12: 2 | N12: 3 | O12: 4 | P12: 5
A13: 1 | B13: 14448 | C13: ADITYA RAIHAN OKTAFIANTO
A14: 2 | B14: 14449 | C14: ADLIG IRYA RAMADHAN
A15: 3 | B15: 14450 | C15: ALFIN ARUL DEKKA MAHENDRA
A16: 4 | B16: 14451 | C16: ANGGER NDARU MUSTAQIIM
A17: 5 | B17: 14452 | C17: ARYA WEDHA NOER MUNIP
A18: 6 | B18: 14453 | C18: AZKA ANDRA SAPUTRA
A19: 7 | B19: 14454 | C19: DAVA MUHAMAD CHARLY
A20: 8 | B20: 14455 | C20: DZAKY AHMAD ZAIDAN
A21: 9 | B21: 14456 | C21: FAIQUNA RIZQI
A22: 10 | B22: 14457 | C22: FALDHAN ARDIANSYAH
A23: 11 | B23: 14458 | C23: FATHIYAN GHAEZA RAFEF
A24: 12 | B24: 14459 | C24: FAUZ EGA RAMADHAN
... A43: 31 | B43: 14479 | C43: ZULFIKAR FADHIL ADYATAMA
A44: 32
A45: 33
A46: 34
A47: 35
A48: 36
A50: CATATAN HARIAN GURU | L50: Deskripsi Penilaian
A51: NO | B51: Tanggal | C51: Kegiatan Pembelajaran | D51: Materi Pembelajaran
A52: 1 | C52: Menerangkan/Diskusi/Tugas/Ujian*) | L52: 1
A53: 2 | C53: Menerangkan/Diskusi/Tugas/Ujian*) | L53: 2
A54: 3 | C54: Menerangkan/Diskusi/Tugas/Ujian*) | L54: 3
A55: 4 | C55: Menerangkan/Diskusi/Tugas/Ujian*) | L55: 4
A56: 5 | C56: Menerangkan/Diskusi/Tugas/Ujian*) | L56: 5
A57: Keterangan : | K57: Bantul,……………………………………….
A58: Penilaian diisikan setiap kali melakukan penilaian harian berupa tugas, tes tertulis, tes lisan, tes unjuk kerja atau portopolio ( Validasi setiap Bulan ) | K58: Guru Bidang Studi
A60: *) Pada kolom kegiatan pembelajaran coret yang tidak dilakukan, kegiatan pembelajaran bisa lebih dari satu kegiatan
K61: …………………………………………….
...

Sheet TKR 2
M1: KUR/PPB/FO-002
M2: Rev. 03 / 25 Juli 2025
A3: DAFTAR HADIR SISWA
A4: ( CATATAN HARIAN GURU DAN DAFTAR NILAI )
A5: SMK MUHAMMADIYAH 1 BANTUL
A6: KELAS : X TKR 2 / TO 2
A8: MATA PELAJARAN :.................................................. | L8: SEMESTER :..................
A9: GURU MATA PELAJARAN :.................................................. | L9: TAHUN PELAJARAN : 2025/2026
A10: WALI AMANAH | C10: : Devan Alfianto, S.Pd
A11: NOMOR | C11: NAMA | D11: BULAN : | I11: JUMLAH | L11: Nilai Tugas Harian | Q11: Nilai KD
A12: URUT | B12: INDUK | I12: S | J12: I | K12: A | L12: 1 | M12: 2 | N12: 3 | O12: 4 | P12: 5
A13: 1 | B13: 14480 | C13: AFDHALUL IKHSAN RASHIF
A14: 2 | B14: 14481 | C14: AGUS DWI RIYANTO
A15: 3 | B15: 14482 | C15: AHMAD FARID PRASETYO
A16: 4 | B16: 14483 | C16: ALIAZA RASID
A17: 5 | B17: 14484 | C17: ALPIN CANDRA BAGASKARA
A18: 6 | B18: 14485 | C18: ANDIKA HENDRI HANSYAH
A19: 7 | B19: 14486 | C19: DAFA EZAR MUNARWAN SAPUTRA
A20: 8 | B20: 14487 | C20: DAFIN JUWIANANTA
A21: 9 | B21: 14488 | C21: DHIA ATHA RAMADHAN
A22: 10 | B22: 14489 | C22: DICKY FAHREIZY
A23: 11 | B23: 14807 | C23: DOKKA UMAROV ABDURAHMAN
A24: 12 | B24: 14490 | C24: DWI RIZIQI NUGROHO
... A46: 34 | B46: 14512 | C46: ZULANO FARIS HABIBI PUTRA
A47: 35
A48: 36
A50: CATATAN HARIAN GURU | L50: Deskripsi Penilaian
A51: NO | B51: Tanggal | C51: Kegiatan Pembelajaran | D51: Materi Pembelajaran
A52: 1 | C52: Menerangkan/Diskusi/Tugas/Ujian*) | L52: 1
A53: 2 | C53: Menerangkan/Diskusi/Tugas/Ujian*) | L53: 2
A54: 3 | C54: Menerangkan/Diskusi/Tugas/Ujian*) | L54: 3
A55: 4 | C55: Menerangkan/Diskusi/Tugas/Ujian*) | L55: 4
A56: 5 | C56: Menerangkan/Diskusi/Tugas/Ujian*) | L56: 5
A57: Keterangan : | K57: Bantul,……………………………………….
A58: Penilaian diisikan setiap kali melakukan penilaian harian berupa tugas, tes tertulis, tes lisan, tes unjuk kerja atau portopolio ( Validasi setiap Bulan ) | K58: Guru Bidang Studi
A60: *) Pada kolom kegiatan pembelajaran coret yang tidak dilakukan, kegiatan pembelajaran bisa lebih dari satu kegiatan
K61: …………………………………………….
K62: NBM…………………………………….
A64: *) 23-sep-2025

Sheet TKR 3
M1: KUR/PPB/FO-002
M2: Rev. 03 / 25 Juli 2025
A3: DAFTAR HADIR SISWA
A4: ( CATATAN HARIAN GURU DAN DAFTAR NILAI )
A5: SMK MUHAMMADIYAH 1 BANTUL
A6: KELAS : X TKR 3 / TO 3
A8: MATA PELAJARAN :.................................................. | L8: SEMESTER :..................
A9: GURU MATA PELAJARAN :.................................................. | L9: TAHUN PELAJARAN : 2025/2026
A10: WALI AMANAH | C10: : Eswantini, S.Pd
A11: NOMOR | C11: NAMA | D11: BULAN : | I11: JUMLAH | L11: Nilai Tugas Harian | Q11: Nilai KD
A12: URUT | B12: INDUK | I12: S | J12: I | K12: A | L12: 1 | M12: 2 | N12: 3 | O12: 4 | P12: 5
A13: 1 | B13: 14513 | C13: ADE IKHSAN MAHENDRA
A14: 2 | B14: 14514 | C14: AHMAD FASHIHULISAN
A15: 3 | B15: 14515 | C15: AHNAF RASYA WILIANSYAH
A16: 4 | B16: 14516 | C16: AL AFIQ
A17: 5 | B17: 14517 | C17: ARYA BIMA SAPUTRA
A18: 6 | B18: 14518 | C18: BAGAS SETIAWAN
A19: 7 | B19: 14519 | C19: DIAZ ADITYA RIZQI AKBAR
A20: 8 | B20: 14520 | C20: DZAKI CHESTA ADABI
A21: 9 | B21: 14521 | C21: EVAN FADHIL ARGANA
A22: 10 | B22: 14522 | C22: FIRMAN ANTONI
A23: 11 | B23: 14523 | C23: GHALIB AFFANDI
A24: 12 | B24: 14524 | C24: HIROSY VINNO PRATAMA
... A43: 31 | B43: 14543 | C43: YUDA RADITIA ROMADHON
A44: 32
A45: 33
A46: 34
A47: 35
A48: 36
A50: CATATAN HARIAN GURU | L50: Deskripsi Penilaian
A51: NO | B51: Tanggal | C51: Kegiatan Pembelajaran | D51: Materi Pembelajaran
A52: 1 | C52: Menerangkan/Diskusi/Tugas/Ujian*) | L52: 1
A53: 2 | C53: Menerangkan/Diskusi/Tugas/Ujian*) | L53: 2
A54: 3 | C54: Menerangkan/Diskusi/Tugas/Ujian*) | L54: 3
A55: 4 | C55: Menerangkan/Diskusi/Tugas/Ujian*) | L55: 4
A56: 5 | C56: Menerangkan/Diskusi/Tugas/Ujian*) | L56: 5
A57: Keterangan : | K57: Bantul,……………………………………….
A58: Penilaian diisikan setiap kali melakukan penilaian harian berupa tugas, tes tertulis, tes lisan, tes unjuk kerja atau portopolio ( Validasi setiap Bulan ) | K58: Guru Bidang Studi
A60: *) Pada kolom kegiatan pembelajaran coret yang tidak dilakukan, kegiatan pembelajaran bisa lebih dari satu kegiatan
K61: …………………………………………….
...

Sheet TKR 4
M1: KUR/PPB/FO-002
M2: Rev. 03 / 25 Juli 2025
A3: DAFTAR HADIR SISWA
A4: ( CATATAN HARIAN GURU DAN DAFTAR NILAI )
A5: SMK MUHAMMADIYAH 1 BANTUL
A6: KELAS : X TKR 4 / TO 4
A8: MATA PELAJARAN :.................................................. | L8: SEMESTER :..................
A9: GURU MATA PELAJARAN :.................................................. | L9: TAHUN PELAJARAN : 2025/2026
A10: WALI AMANAH | C10: : Uswatun Hasanah, S.Pd.I
A11: NOMOR | C11: NAMA | D11: BULAN : | I11: JUMLAH | L11: Nilai Tugas Harian | Q11: Nilai KD
A12: URUT | B12: INDUK | I12: S | J12: I | K12: A | L12: 1 | M12: 2 | N12: 3 | O12: 4 | P12: 5
A13: 1 | B13: 14544 | C13: ABDUL MUHYI RIZZAH
A14: 2 | B14: 14545 | C14: AHMAD IKHSAN
A15: 3 | B15: 14546 | C15: AHMAT YASIR AL GHIFARI
A16: 4 | B16: 14547 | C16: ALVIN FEBRIANO TEGAR SETYAWAN
A17: 5 | B17: 14548 | C17: ANDI RIDHODWI FIRMANSYA
A18: 6 | B18: 14549 | C18: ANDRA RAMADHAN
A19: 7 | B19: 14550 | C19: ARFIAN RIZKY NUR RAMADHAN
A20: 8 | B20: 14551 | C20: AULIA MEIKA PUTRI ARSYA
A21: 9 | B21: 14552 | C21: AZZAKI KAMAL FIRDAUS
A22: 10 | B22: 14553 | C22: BANYU SATRIO NUGROHO
A23: 11 | B23: 14554 | C23: DENDRI ALPON BERTAK SYAH
A24: 12 | B24: 14555 | C24: DIKA PUTRA PRATAMA
... A46: 34 | B46: 14577 | C46: WAKHID SEPTIANWAR ROMADHAN
A47: 35
A48: 36
A50: CATATAN HARIAN GURU | L50: Deskripsi Penilaian
A51: NO | B51: Tanggal | C51: Kegiatan Pembelajaran | D51: Materi Pembelajaran
A52: 1 | C52: Menerangkan/Diskusi/Tugas/Ujian*) | L52: 1
A53: 2 | C53: Menerangkan/Diskusi/Tugas/Ujian*) | L53: 2
A54: 3 | C54: Menerangkan/Diskusi/Tugas/Ujian*) | L54: 3
A55: 4 | C55: Menerangkan/Diskusi/Tugas/Ujian*) | L55: 4
A56: 5 | C56: Menerangkan/Diskusi/Tugas/Ujian*) | L56: 5
A57: Keterangan : | K57: Bantul,……………………………………….
A58: Penilaian diisikan setiap kali melakukan penilaian harian berupa tugas, tes tertulis, tes lisan, tes unjuk kerja atau portopolio ( Validasi setiap Bulan ) | K58: Guru Bidang Studi
A60: *) Pada kolom kegiatan pembelajaran coret yang tidak dilakukan, kegiatan pembelajaran bisa lebih dari satu kegiatan
K61: …………………………………………….
K62: NBM…………………………………….
A64: *) 23-jul-2025

Sheet TKR 5
M1: KUR/PPB/FO-002
M2: Rev. 03 / 25 Juli 2025
A3: DAFTAR HADIR SISWA
A4: ( CATATAN HARIAN GURU DAN DAFTAR NILAI )
A5: SMK MUHAMMADIYAH 1 BANTUL
A6: KELAS : X TKR 5 / TO 5
A8: MATA PELAJARAN :.................................................. | L8: SEMESTER :..................
A9: GURU MATA PELAJARAN :.................................................. | L9: TAHUN PELAJARAN : 2025/2026
A10: WALI AMANAH | C10: : Ida Nuryanti, S.Pd
A11: NOMOR | C11: NAMA | D11: BULAN : | I11: JUMLAH | L11: Nilai Tugas Harian | Q11: Nilai KD
A12: URUT | B12: INDUK | I12: S | J12: I | K12: A | L12: 1 | M12: 2 | N12: 3 | O12: 4 | P12: 5
A13: 1 | B13: 14578 | C13: ADIMAS AGUNG SAPUTRA
A14: 2 | B14: 14579 | C14: AGASTA GHERY SAPUTRA
A15: 3 | B15: 14580 | C15: ALAN KURNIAWAN SUBEKTY
A16: 4 | B16: 14581 | C16: ANANDA RIZKY PRASETYO WIDODO
A17: 5 | B17: 14582 | C17: AQIELA ZAKI NANDANA HAWASIA
A18: 6 | B18: 14583 | C18: AZKA ALIYAN HAKMANI
A19: 7 | B19: 14584 | C19: DAFFA ARYA SADEWA
A20: 8 | B20: 14585 | C20: DIMAS PUTRA PRATAMA
A21: 9 | B21: 14586 | C21: EMAN IANZA
A22: 10 | B22: 14587 | C22: FAHREZI ISNAN KURNIAWAN
A23: 11 | B23: 14588 | C23: FAREL AGUSTIAN SAPUTRA
A24: 12 | B24: 14589 | C24: HAFIIZH SODIK NURRAHMAN
... A42: 30 | B42: 14607 | C42: ZUHDA MUSAHILA
A43: 31
A44: 32
A45: 33
A46: 34
A47: 35
A48: 36
A50: CATATAN HARIAN GURU | L50: Deskripsi Penilaian
A51: NO | B51: Tanggal | C51: Kegiatan Pembelajaran | D51: Materi Pembelajaran
A52: 1 | C52: Menerangkan/Diskusi/Tugas/Ujian*) | L52: 1
A53: 2 | C53: Menerangkan/Diskusi/Tugas/Ujian*) | L53: 2
A54: 3 | C54: Menerangkan/Diskusi/Tugas/Ujian*) | L54: 3
A55: 4 | C55: Menerangkan/Diskusi/Tugas/Ujian*) | L55: 4
A56: 5 | C56: Menerangkan/Diskusi/Tugas/Ujian*) | L56: 5
A57: Keterangan : | K57: Bantul,……………………………………….
A58: Penilaian diisikan setiap kali melakukan penilaian harian berupa tugas, tes tertulis, tes lisan, tes unjuk kerja atau portopolio ( Validasi setiap Bulan ) | K58: Guru Bidang Studi
A60: *) Pada kolom kegiatan pembelajaran coret yang tidak dilakukan, kegiatan pembelajaran bisa lebih dari satu kegiatan
...

Sheet TSM 1
M1: KUR/PPB/FO-002
M2: Rev. 03 / 25 Juli 2025
A3: DAFTAR HADIR SISWA
A4: ( CATATAN HARIAN GURU DAN DAFTAR NILAI )
A5: SMK MUHAMMADIYAH 1 BANTUL
A6: KELAS : X TSM 1 / TO 6
A8: MATA PELAJARAN :.................................................. | L8: SEMESTER :..................
A9: GURU MATA PELAJARAN :.................................................. | L9: TAHUN PELAJARAN : 2025/2026
A10: WALI AMANAH | C10: : Anjar Eko Wibowo, S.Pd
A11: NOMOR | C11: NAMA | D11: BULAN : | I11: JUMLAH | L11: Nilai Tugas Harian | Q11: Nilai KD
A12: URUT | B12: INDUK | I12: S | J12: I | K12: A | L12: 1 | M12: 2 | N12: 3 | O12: 4 | P12: 5
A13: 1 | B13: 14608 | C13: ABYAN MAHMUD ANSHORI
A14: 2 | B14: 14609 | C14: AFGA DWI CAHYO
A15: 3 | B15: 14610 | C15: AFRIANSYAH ALIF'FA SYAPUTRA
A16: 4 | B16: 14611 | C16: AGUSTINA VELIKA RAMADHANI
A17: 5 | B17: 14612 | C17: AHMAD HAFIZ MAULANA
A18: 6 | B18: 14613 | C18: AHMAD ROSSID
A19: 7 | B19: 14614 | C19: AHMAD SALVA BALLESTA LUAY KUSUMA
A20: 8 | B20: 14615 | C20: AHNAF LAILANO MUKASA DHIYAA - ULHAQ
A21: 9 | B21: 14617 | C21: AKBAR NUR SYAH PUTRA
A22: 10 | B22: 14618 | C22: AKBAR PUTRA QURNIAWAN
A23: 11 | B23: 14619 | C23: ALFIAN ANDRI ANSYAH
A24: 12 | B24: 14620 | C24: ALI NURFIANO
... A45: 33 | B45: 14641 | C45: ZIDAN MARVINO
A46: 34
A47: 35
A48: 36
A50: CATATAN HARIAN GURU | L50: Deskripsi Penilaian
A51: NO | B51: Tanggal | C51: Kegiatan Pembelajaran | D51: Materi Pembelajaran
A52: 1 | C52: Menerangkan/Diskusi/Tugas/Ujian*) | L52: 1
A53: 2 | C53: Menerangkan/Diskusi/Tugas/Ujian*) | L53: 2
A54: 3 | C54: Menerangkan/Diskusi/Tugas/Ujian*) | L54: 3
A55: 4 | C55: Menerangkan/Diskusi/Tugas/Ujian*) | L55: 4
A56: 5 | C56: Menerangkan/Diskusi/Tugas/Ujian*) | L56: 5
A57: Keterangan : | K57: Bantul,……………………………………….
A58: Penilaian diisikan setiap kali melakukan penilaian harian berupa tugas, tes tertulis, tes lisan, tes unjuk kerja atau portopolio ( Validasi setiap Bulan ) | K58: Guru Bidang Studi
A60: *) Pada kolom kegiatan pembelajaran coret yang tidak dilakukan, kegiatan pembelajaran bisa lebih dari satu kegiatan
K61: …………………………………………….
K62: NBM…………………………………….
A64: *) 23-sep-2025

Sheet TSM 2
M1: KUR/PPB/FO-002
M2: Rev. 03 / 25 Juli 2025
A3: DAFTAR HADIR SISWA
A4: ( CATATAN HARIAN GURU DAN DAFTAR NILAI )
A5: SMK MUHAMMADIYAH 1 BANTUL
A6: KELAS : X TSM 2 / TO 7
A8: MATA PELAJARAN :.................................................. | L8: SEMESTER :..................
A9: GURU MATA PELAJARAN :.................................................. | L9: TAHUN PELAJARAN : 2025/2026
A10: WALI AMANAH | C10: : Rully Mal Aziz, S.Pd
A11: NOMOR | C11: NAMA | D11: BULAN : | I11: JUMLAH | L11: Nilai Tugas Harian | Q11: Nilai KD
A12: URUT | B12: INDUK | I12: S | J12: I | K12: A | L12: 1 | M12: 2 | N12: 3 | O12: 4 | P12: 5
A13: 1 | B13: 14642 | C13: AAN ADITYA JAYAMURTI
A14: 2 | B14: 14643 | C14: ADRIAN REZKY SAPUTRA
A15: 3 | B15: 14644 | C15: ALAUDIN BARIQ FAISA
A16: 4 | B16: 14645 | C16: CHARLIE NAZRIL ARDIANTO
A17: 5 | B17: 14646 | C17: DAFA NUR RAHMAN
A18: 6 | B18: 14647 | C18: DANIES ARKA WAHANA
A19: 7 | B19: 14648 | C19: DEFFAN AUGUSTALIANO HERDEANPUTRA
A20: 8 | B20: 14649 | C20: DIMAS RAKA
A21: 9 | B21: 14650 | C21: DWI NUR CAHYO
A22: 10 | B22: 14651 | C22: FAHDAN HAFIDZ IKHWANTORO
A23: 11 | B23: 14652 | C23: FAIZASYAH SETO PRASETIYO
A24: 12 | B24: 14653 | C24: FERISCHO RICKY SAPUTRA
... A44: 32 | B44: 14673 | C44: YUSUF ANNAS BAHTIAR
A45: 33
A46: 34
A47: 35
A48: 36
A50: CATATAN HARIAN GURU | L50: Deskripsi Penilaian
A51: NO | B51: Tanggal | C51: Kegiatan Pembelajaran | D51: Materi Pembelajaran
A52: 1 | C52: Menerangkan/Diskusi/Tugas/Ujian*) | L52: 1
A53: 2 | C53: Menerangkan/Diskusi/Tugas/Ujian*) | L53: 2
A54: 3 | C54: Menerangkan/Diskusi/Tugas/Ujian*) | L54: 3
A55: 4 | C55: Menerangkan/Diskusi/Tugas/Ujian*) | L55: 4
A56: 5 | C56: Menerangkan/Diskusi/Tugas/Ujian*) | L56: 5
A57: Keterangan : | K57: Bantul,……………………………………….
A58: Penilaian diisikan setiap kali melakukan penilaian harian berupa tugas, tes tertulis, tes lisan, tes unjuk kerja atau portopolio ( Validasi setiap Bulan ) | K58: Guru Bidang Studi
A60: *) Pada kolom kegiatan pembelajaran coret yang tidak dilakukan, kegiatan pembelajaran bisa lebih dari satu kegiatan
K61: …………………………………………….
K62: NBM…………………………………….
...

Sheet TSM 3
M1: KUR/PPB/FO-002
M2: Rev. 03 / 25 Juli 2025
A3: DAFTAR HADIR SISWA
A4: ( CATATAN HARIAN GURU DAN DAFTAR NILAI )
A5: SMK MUHAMMADIYAH 1 BANTUL
A6: KELAS : X TSM 3 / TO 8
A8: MATA PELAJARAN :.................................................. | L8: SEMESTER :..................
A9: GURU MATA PELAJARAN :.................................................. | L9: TAHUN PELAJARAN : 2025/2026
A10: WALI AMANAH | C10: : Muhammad Ridwan Sulthoni, S.Pd
A11: NOMOR | C11: NAMA | D11: BULAN : | I11: JUMLAH | L11: Nilai Tugas Harian | Q11: Nilai KD
A12: URUT | B12: INDUK | I12: S | J12: I | K12: A | L12: 1 | M12: 2 | N12: 3 | O12: 4 | P12: 5
A13: 1 | B13: 14674 | C13: ABIMANYU WAHYUDI
A14: 2 | B14: 14675 | C14: ARDIAN NADHIF PUTRA
A15: 3 | B15: 14676 | C15: CHASTELANO BARA PUTRA ADRIYAN
A16: 4 | B16: 14677 | C16: DAMAR AGUNG NUGROHO
A17: 5 | B17: 14678 | C17: DARRIEL OBI MARSHALLO
A18: 6 | B18: 14679 | C18: DELVIN FATHIR MUSSLIHUDIN
A19: 7 | B19: 14680 | C19: DHENIA DEWA PRASETYA
A20: 8 | B20: 14681 | C20: DIMAS WAHYUGA
A21: 9 | B21: 14682 | C21: EGGA PRATAMA PUTRA
A22: 10 | B22: 14683 | C22: FAIZ JALU NURYAWAN
A23: 11 | B23: 14684 | C23: FAZZA AVRIL PRATAMA
A24: 12 | B24: 14685 | C24: FERRY ANDRIANSYAH
... A44: 32 | B44: 14705 | C44: ZUDAN SUBEKTI
A45: 33
A46: 34
A47: 35
A48: 36
A50: CATATAN HARIAN GURU | L50: Deskripsi Penilaian
A51: NO | B51: Tanggal | C51: Kegiatan Pembelajaran | D51: Materi Pembelajaran
A52: 1 | C52: Menerangkan/Diskusi/Tugas/Ujian*) | L52: 1
A53: 2 | C53: Menerangkan/Diskusi/Tugas/Ujian*) | L53: 2
A54: 3 | C54: Menerangkan/Diskusi/Tugas/Ujian*) | L54: 3
A55: 4 | C55: Menerangkan/Diskusi/Tugas/Ujian*) | L55: 4
A56: 5 | C56: Menerangkan/Diskusi/Tugas/Ujian*) | L56: 5
A57: Keterangan : | K57: Bantul,……………………………………….
A58: Penilaian diisikan setiap kali melakukan penilaian harian berupa tugas, tes tertulis, tes lisan, tes unjuk kerja atau portopolio ( Validasi setiap Bulan ) | K58: Guru Bidang Studi
A60: *) Pada kolom kegiatan pembelajaran coret yang tidak dilakukan, kegiatan pembelajaran bisa lebih dari satu kegiatan
K61: …………………………………………….
K62: NBM…………………………………….
...

Sheet TSM 4
M1: KUR/PPB/FO-002
M2: Rev. 03 / 25 Juli 2025
A3: DAFTAR HADIR SISWA
A4: ( CATATAN HARIAN GURU DAN DAFTAR NILAI )
A5: SMK MUHAMMADIYAH 1 BANTUL
A6: KELAS : X TSM 4 / TO 9
A8: MATA PELAJARAN :.................................................. | L8: SEMESTER :..................
A9: GURU MATA PELAJARAN :.................................................. | L9: TAHUN PELAJARAN : 2025/2026
A10: WALI AMANAH | C10: : Tono Prihatin, S.Pd
A11: NOMOR | C11: NAMA | D11: BULAN : | I11: JUMLAH | L11: Nilai Tugas Harian | Q11: Nilai KD
A12: URUT | B12: INDUK | I12: S | J12: I | K12: A | L12: 1 | M12: 2 | N12: 3 | O12: 4 | P12: 5
A13: 1 | B13: 14706 | C13: ABDUL FATIH KHOIRUDDIN
A14: 2 | B14: 14707 | C14: ADITYA DWI APRIANTO
A15: 3 | B15: 14708 | C15: ALFIAN JULIAN PUTRA
A16: 4 | B16: 14709 | C16: ARDI YULI KURNIAWAN
A17: 5 | B17: 14710 | C17: ARETHA FATHAN PRATAMA
A18: 6 | B18: 14711 | C18: ARFIYAN RIZKY KURNIAWAN
A19: 7 | B19: 14712 | C19: ARTAMA RAHMAT FAUSTA
A20: 8 | B20: 14713 | C20: AYUB FATURACHMAN
A21: 9 | B21: 14714 | C21: AZIIZ RIZQI SAPUTRO
A22: 10 | B22: 14715 | C22: AZWAN EKA WAHYU FEBRIYANA
A23: 11 | B23: 14716 | C23: BAGUS ARYA MANUNGGAL
A24: 12 | B24: 14717 | C24: BAHRUL ULUM NAFI
... A47: 35 | B47: 14740 | C47: ZAKI RADITYA RUSDIANTO
A48: 36
A50: CATATAN HARIAN GURU | L50: Deskripsi Penilaian
A51: NO | B51: Tanggal | C51: Kegiatan Pembelajaran | D51: Materi Pembelajaran
A52: 1 | C52: Menerangkan/Diskusi/Tugas/Ujian*) | L52: 1
A53: 2 | C53: Menerangkan/Diskusi/Tugas/Ujian*) | L53: 2
A54: 3 | C54: Menerangkan/Diskusi/Tugas/Ujian*) | L54: 3
A55: 4 | C55: Menerangkan/Diskusi/Tugas/Ujian*) | L55: 4
A56: 5 | C56: Menerangkan/Diskusi/Tugas/Ujian*) | L56: 5
A57: Keterangan : | K57: Bantul,……………………………………….
A58: Penilaian diisikan setiap kali melakukan penilaian harian berupa tugas, tes tertulis, tes lisan, tes unjuk kerja atau portopolio ( Validasi setiap Bulan ) | K58: Guru Bidang Studi
A60: *) Pada kolom kegiatan pembelajaran coret yang tidak dilakukan, kegiatan pembelajaran bisa lebih dari satu kegiatan
K61: …………………………………………….
K62: NBM…………………………………….
A64: *) 17-jul-2025

Sheet RPL 1
M1: KUR/PPB/FO-002
M2: Rev. 03 / 25 Juli 2025
A3: DAFTAR HADIR SISWA
A4: ( CATATAN HARIAN GURU DAN DAFTAR NILAI )
A5: SMK MUHAMMADIYAH 1 BANTUL
A6: KELAS : X RPL 1 / PPLG 1
A8: MATA PELAJARAN :.................................................. | L8: SEMESTER :..................
A9: GURU MATA PELAJARAN :.................................................. | L9: TAHUN PELAJARAN : 2025/2026
A10: WALI AMANAH | C10: : Ekayanti Retnaningsih, S.Pd
A11: NOMOR | C11: NAMA | D11: BULAN : | I11: JUMLAH | L11: Nilai Tugas Harian | Q11: Nilai KD
A12: URUT | B12: INDUK | I12: S | J12: I | K12: A | L12: 1 | M12: 2 | N12: 3 | O12: 4 | P12: 5
A13: 1 | B13: 14741 | C13: AHMAD APRIYANTO
A14: 2 | B14: 14742 | C14: AJI SAKA PRATAMA
A15: 3 | B15: 14743 | C15: ALVEYRO JANNY GRACIO
A16: 4 | B16: 14744 | C16: ALYA FADMA DINATA
A17: 5 | B17: 14745 | C17: ANDINI REGINA ARDIYANTI
A18: 6 | B18: 14746 | C18: ARKHA ARDAN PRATAMA
A19: 7 | B19: 14747 | C19: CHELSYA RIZTI
A20: 8 | B20: 14748 | C20: DONI PRATAMA
A21: 9 | B21: 14749 | C21: DZAKY ARRAHMAN
A22: 10 | B22: 14750 | C22: ERLIENDHA PUTRI ELYSHA
A23: 11 | B23: 14751 | C23: EVAN PERDANA PUTRA
A24: 12 | B24: 14752 | C24: FATIHUL IHSAN PUTRA SETIAWAN
... A46: 34 | B46: 14774 | C46: ZAHRI ARDIYANTO
A47: 35
A48: 36
A50: CATATAN HARIAN GURU | L50: Deskripsi Penilaian
A51: NO | B51: Tanggal | C51: Kegiatan Pembelajaran | D51: Materi Pembelajaran
A52: 1 | C52: Menerangkan/Diskusi/Tugas/Ujian*) | L52: 1
A53: 2 | C53: Menerangkan/Diskusi/Tugas/Ujian*) | L53: 2
A54: 3 | C54: Menerangkan/Diskusi/Tugas/Ujian*) | L54: 3
A55: 4 | C55: Menerangkan/Diskusi/Tugas/Ujian*) | L55: 4
A56: 5 | C56: Menerangkan/Diskusi/Tugas/Ujian*) | L56: 5
A57: Keterangan : | K57: Bantul,……………………………………….
A58: Penilaian diisikan setiap kali melakukan penilaian harian berupa tugas, tes tertulis, tes lisan, tes unjuk kerja atau portopolio ( Validasi setiap Bulan ) | K58: Guru Bidang Studi
A60: *) Pada kolom kegiatan pembelajaran coret yang tidak dilakukan, kegiatan pembelajaran bisa lebih dari satu kegiatan
K61: …………………………………………….
K62: NBM…………………………………….
A64: *) 25-jul-2025

Sheet RPL 2
M1: KUR/PPB/FO-002
M2: Rev. 03 / 25 Juli 2025
A3: DAFTAR HADIR SISWA
A4: ( CATATAN HARIAN GURU DAN DAFTAR NILAI )
A5: SMK MUHAMMADIYAH 1 BANTUL
A6: KELAS : X RPL 2 / PPLG 2
A8: MATA PELAJARAN :.................................................. | L8: SEMESTER :..................
A9: GURU MATA PELAJARAN :.................................................. | L9: TAHUN PELAJARAN : 2025/2026
A10: WALI AMANAH | C10: : Heni Purwantari Utami, S.Pd
A11: NOMOR | C11: NAMA | D11: BULAN : | I11: JUMLAH | L11: Nilai Tugas Harian | Q11: Nilai KD
A12: URUT | B12: INDUK | I12: S | J12: I | K12: A | L12: 1 | M12: 2 | N12: 3 | O12: 4 | P12: 5
A13: 1 | B13: 14775 | C13: ADE NANDA PUTRI YASVA
A14: 2 | B14: 14776 | C14: ADI PRASETYO
A15: 3 | B15: 14777 | C15: ADITYA SADEWA
A16: 4 | B16: 14778 | C16: ANDREAN SATRIO NUGROHO
A17: 5 | B17: 14779 | C17: ANJANI LARASATI AZIZAH
A18: 6 | B18: 14780 | C18: ANNISA MAHDALENA
A19: 7 | B19: 14781 | C19: ARGA PRADISA PUTRA RAMADHANI
A20: 8 | B20: 14782 | C20: DEVASYHA AQUILA MAULANA
A21: 9 | B21: 14783 | C21: DZAKIY RAHADYAN PRAMONO
A22: 10 | B22: 14784 | C22: ELLENA DWI PUSPITA SARI
A23: 11 | B23: 14785 | C23: FAJAR KUSUMA AJI
A24: 12 | B24: 14786 | C24: FARID NUR PRASETYO
... A43: 31 | B43: 14805 | C43: ZULI DWI PITRIYANI
A44: 32
A45: 33
A46: 34
A47: 35
A48: 36
A50: CATATAN HARIAN GURU | L50: Deskripsi Penilaian
A51: NO | B51: Tanggal | C51: Kegiatan Pembelajaran | D51: Materi Pembelajaran
A52: 1 | C52: Menerangkan/Diskusi/Tugas/Ujian*) | L52: 1
A53: 2 | C53: Menerangkan/Diskusi/Tugas/Ujian*) | L53: 2
A54: 3 | C54: Menerangkan/Diskusi/Tugas/Ujian*) | L54: 3
A55: 4 | C55: Menerangkan/Diskusi/Tugas/Ujian*) | L55: 4
A56: 5 | C56: Menerangkan/Diskusi/Tugas/Ujian*) | L56: 5
A57: Keterangan : | K57: Bantul,……………………………………….
A58: Penilaian diisikan setiap kali melakukan penilaian harian berupa tugas, tes tertulis, tes lisan, tes unjuk kerja atau portopolio ( Validasi setiap Bulan ) | K58: Guru Bidang Studi
A60: *) Pada kolom kegiatan pembelajaran coret yang tidak dilakukan, kegiatan pembelajaran bisa lebih dari satu kegiatan
K61: …………………………………………….
...

Sheet stat
A1: NO | B1: KELAS | C1: JUMLAH
A2: 1 | B2: X TAV / TE | C2: =COUNTA('TAV 1'!$C$13:$C$32) -> 13
A3: 2 | B3: X TPM 1 / TM 1 | C3: =COUNTA('TPM 1'!$C$13:$C$46) -> 29 | E3: NIS TERAKHIR : | H3: 14807 | I3: DOKKA UMAROV ABDURAHMAN | J3: 10 PPLG 2
A4: 3 | B4: X TPM 2 / TM 2 | C4: =COUNTA('TPM 2'!$C$13:$C$48) -> 30
A5: 4 | B5: X TKR 1 / TO 1 | C5: =COUNTA('TKR 1'!$C$13:$C$48) -> 31
A6: 5 | B6: X TKR 2 / TO 2 | C6: =COUNTA('TKR 2'!$C$13:$C$48) -> 34
A7: 6 | B7: X TKR 3 / TO 3 | C7: =COUNTA('TKR 3'!$C$13:$C$49) -> 31
A8: 7 | B8: X TKR 4 / TO 4 | C8: =COUNTA('TKR 4'!$C$13:$C$49) -> 34
A9: 8 | B9: X TKR 5 / TO 5 | C9: =COUNTA('TKR 5'!$C$13:$C$49) -> 30
A10: 9 | B10: X TSM 1 / TO 6 | C10: =COUNTA('TSM 1'!$C$13:$C$49) -> 33
A11: 10 | B11: X TSM 2 / TO 7 | C11: =COUNTA('TSM 2'!$C$13:$C$49) -> 32
A12: 11 | B12: X TSM 3 / TO 8 | C12: =COUNTA('TSM 3'!$C$13:$C$49) -> 32
A13: 12 | B13: X TSM 4 / TO 9 | C13: =COUNTA('TSM 4'!$C$13:$C$49) -> 35
A14: 13 | B14: X RPL 1 / PPLG 1 | C14: =COUNTA('RPL 1'!$C$13:$C$48) -> 34
A15: 14 | B15: X RPL 2 / PPLG 2 | C15: =COUNTA('RPL 2'!$C$13:$C$48) -> 31
B16: TOTAL | C16: =SUM(C2:C15) -> 429

Sheet Total
A1: NO | B1: NIS | C1: NAMA SISWA | D1: KELAS | E1: KELAS 2 | F1: KET | G1: NIS | I1: JURUSAN | J1: JUMLAH AWAL | K1: ROMBEL | L1: AKTIF | M1: KELUAR | N1: TOTAL AKTIF | O1: TOTAL KELUAR
A2: 1 | B2: 14375 | C2: ARIF YUSUF MAULANA | D2: 10 TAV | E2: 10 TE | F2: AKTIF | G2: 14375 | I2: TE / TAV | J2: =N2+O2 -> 13 | K2: 1 | L2: =COUNTIFS($E$2:$E$439,"10 TE",$F$2:$F$439,"AKTIF") -> 13 | M2: =COUNTIFS($E$2:$E$439,"10 TE",$F$2:$F$439,"KELUAR") -> 0 | N2: =SUM(L2) -> 13 | O2: =SUM(M2) -> 0
A3: 2 | B3: 14376 | C3: AZRIEL GALANG NURKHOLIS | D3: 10 TAV | E3: 10 TE | F3: AKTIF | G3: 14376 | I3: TM / TPM | J3: =N3+O3 -> 61 | K3: 1 | L3: =COUNTIFS($E$2:$E$439,"10 TM 1",$F$2:$F$439,"AKTIF") -> 29 | M3: =COUNTIFS($E$2:$E$439,"10 TM 1",$F$2:$F$439,"KELUAR") -> 2 | N3: =SUM(L3:L4) -> 59 | O3: =SUM(M3:M4) -> 2
A4: 3 | B4: 14377 | C4: BAYU AJI NUGROHO | D4: 10 TAV | E4: 10 TE | F4: AKTIF | G4: 14377 | K4: 2 | L4: =COUNTIFS($E$2:$E$439,"10 TM 2",$F$2:$F$439,"AKTIF") -> 30 | M4: =COUNTIFS($E$2:$E$439,"10 TM 2",$F$2:$F$439,"KELUAR") -> 0
A5: 4 | B5: 14378 | C5: MAULANA QOLBI | D5: 10 TAV | E5: 10 TE | F5: AKTIF | G5: 14378 | I5: TO / TKRO | J5: =N5+O5 -> 161 | K5: 1 | L5: =COUNTIFS($E$2:$E$439,"10 TO 1",$F$2:$F$439,"AKTIF") -> 31 | M5: =COUNTIFS($E$2:$E$439,"10 TO 1",$F$2:$F$439,"KELUAR") -> 1 | N5: =SUM(L5:L9) -> 160 | O5: =SUM(M5:M9) -> 1
A6: 5 | B6: 14379 | C6: MERLIN PUTRI RAMADHANI | D6: 10 TAV | E6: 10 TE | F6: AKTIF | G6: 14379 | K6: 2 | L6: =COUNTIFS($E$2:$E$439,"10 TO 2",$F$2:$F$439,"AKTIF") -> 34 | M6: =COUNTIFS($E$2:$E$439,"10 TO 2",$F$2:$F$439,"KELUAR") -> 0
A7: 6 | B7: 14380 | C7: MUHAMMAD AKBAR | D7: 10 TAV | E7: 10 TE | F7: AKTIF | G7: 14380 | K7: 3 | L7: =COUNTIFS($E$2:$E$439,"10 TO 3",$F$2:$F$439,"AKTIF") -> 31 | M7: =COUNTIFS($E$2:$E$439,"10 TO 3",$F$2:$F$439,"KELUAR") -> 0
A8: 7 | B8: 14381 | C8: MUHAMMAD HASBY | D8: 10 TAV | E8: 10 TE | F8: AKTIF | G8: 14381 | K8: 4 | L8: =COUNTIFS($E$2:$E$439,"10 TO 4",$F$2:$F$439,"AKTIF") -> 34 | M8: =COUNTIFS($E$2:$E$439,"10 TO 4",$F$2:$F$439,"KELUAR") -> 0
A9: 8 | B9: 14382 | C9: NANDA BAGUS DWI FIRMANSYAH | D9: 10 TAV | E9: 10 TE | F9: AKTIF | G9: 14382 | K9: 5 | L9: =COUNTIFS($E$2:$E$439,"10 TO 5",$F$2:$F$439,"AKTIF") -> 30 | M9: =COUNTIFS($E$2:$E$439,"10 TO 5",$F$2:$F$439,"KELUAR") -> 0
A10: 9 | B10: 14383 | C10: NIZA NARENDRA KARUNIA GUSTI | D10: 10 TAV | E10: 10 TE | F10: AKTIF | G10: 14383 | I10: TO / TBSM | J10: =N10+O10 -> 133 | K10: 1 | L10: =COUNTIFS($E$2:$E$439,"10 TO 6",$F$2:$F$439,"AKTIF") -> 33 | M10: =COUNTIFS($E$2:$E$439,"10 TO 6",$F$2:$F$439,"KELUAR") -> 1 | N10: =SUM(L10:L13) -> 132 | O10: =SUM(M10:M13) -> 1
A11: 10 | B11: 14384 | C11: RAIZ PANJI SAPUTRO | D11: 10 TAV | E11: 10 TE | F11: AKTIF | G11: 14384 | K11: 2 | L11: =COUNTIFS($E$2:$E$439,"10 TO 7",$F$2:$F$439,"AKTIF") -> 32 | M11: =COUNTIFS($E$2:$E$439,"10 TO 7",$F$2:$F$439,"KELUAR") -> 0
A12: 11 | B12: 14385 | C12: RAZAQA ADITYA FAZA | D12: 10 TAV | E12: 10 TE | F12: AKTIF | G12: 14385 | K12: 3 | L12: =COUNTIFS($E$2:$E$439,"10 TO 8",$F$2:$F$439,"AKTIF") -> 32 | M12: =COUNTIFS($E$2:$E$439,"10 TO 8",$F$2:$F$439,"KELUAR") -> 0
A13: 12 | B13: 14386 | C13: RIDWAN MAULANA | D13: 10 TAV | E13: 10 TE | F13: AKTIF | G13: 14386 | K13: 4 | L13: =COUNTIFS($E$2:$E$439,"10 TO 9",$F$2:$F$439,"AKTIF") -> 35 | M13: =COUNTIFS($E$2:$E$439,"10 TO 9",$F$2:$F$439,"KELUAR") -> 0
A14: 13 | B14: 14387 | C14: VANO PUTRA PERDANA WIJAYA | D14: 10 TAV | E14: 10 TE | F14: AKTIF | G14: 14387 | I14: PPLG / RPL | J14: =N14+O14 -> 65 | K14: 1 | L14: =COUNTIFS($E$2:$E$439,"10 PPLG 1",$F$2:$F$439,"AKTIF") -> 34 | M14: =COUNTIFS($E$2:$E$439,"10 PPLG 1",$F$2:$F$439,"KELUAR") -> 0 | N14: =SUM(L14:L15) -> 65 | O14: =SUM(M14:M15) -> 0
A15: 14 | B15: 14388 | C15: ADNAN AS SYIFA CANDRA WIBAWA | D15: 10 TPM 1 | E15: 10 TM 1 | F15: AKTIF | G15: 14388 | K15: 2 | L15: =COUNTIFS($E$2:$E$439,"10 PPLG 2",$F$2:$F$439,"AKTIF") -> 31 | M15: =COUNTIFS($E$2:$E$439,"10 PPLG 2",$F$2:$F$439,"KELUAR") -> 0
A16: 15 | B16: 14389 | C16: AHMAD AFIQ MAULANA | D16: 10 TPM 1 | E16: 10 TM 1 | F16: AKTIF | G16: 14389 | I16: TOTAL | J16: =SUM(J2:J14) -> 433 | K16: =COUNTA(K2:K15) -> 14 | L16: =SUM(L2:L15) -> 429 | M16: =SUM(M2:M15) -> 4 | N16: =SUM(N2:N15) -> 429 | O16: =SUM(O2:O15) -> 4
A17: 16 | B17: 14390 | C17: ALFAREL FRIDZI NAUVALADI | D17: 10 TPM 1 | E17: 10 TM 1 | F17: AKTIF | G17: 14390
A18: 17 | B18: 14391 | C18: ASYRAF AULIA RAHMAN | D18: 10 TPM 1 | E18: 10 TM 1 | F18: AKTIF | G18: 14391
A19: 18 | B19: 14392 | C19: ATHAR AL FATIH IBROHIM | D19: 10 TPM 1 | E19: 10 TM 1 | F19: AKTIF | G19: 14392
A20: 19 | B20: 14393 | C20: BAGAS ARDHI PANGESTU | D20: 10 TPM 1 | E20: 10 TM 1 | F20: AKTIF | G20: 14393
A21: 20 | B21: 14394 | C21: BINTANG RADITHYA JAVAS NARARYA | D21: 10 TPM 1 | E21: 10 TM 1 | F21: AKTIF | G21: 14394
A22: 21 | B22: 14395 | C22: BIRLIANZA GAHZY ARVEL ARISQI | D22: 10 TPM 1 | E22: 10 TM 1 | F22: AKTIF | G22: 14395
A23: 22 | B23: 14396 | C23: CAESAR GANENDRA DEVLIN | D23: 10 TPM 1 | E23: 10 TM 1 | F23: AKTIF | G23: 14396
A24: 23 | B24: 14397 | C24: FADLI SYAIFUDIN ILHAM | D24: 10 TPM 1 | E24: 10 TM 1 | F24: AKTIF | G24: 14397
A25: 24 | B25: 14398 | C25: FAJAR DWI NUGROHO | D25: 10 TPM 1 | E25: 10 TM 1 | F25: AKTIF | G25: 14398
A26: 25 | B26: 14399 | C26: FAREL ADITYA PRATAMA | D26: 10 TPM 1 | E26: 10 TM 1 | F26: AKTIF | G26: 14399
A27: 26 | B27: 14400 | C27: HAFIDZ ISANKA YAHYA | D27: 10 TPM 1 | E27: 10 TM 1 | F27: AKTIF | G27: 14400
A28: 27 | B28: 14401 | C28: HUSEIN SYA'ID ABDULLAH | D28: 10 TPM 1 | E28: 10 TM 1 | F28: AKTIF | G28: 14401
... A434: 433 | B434: 14805 | C434: ZULI DWI PITRIYANI | D434: 10 RPL 2 | E434: 10 PPLG 2 | F434: AKTIF | G434: 14805
A435: 434
A436: 435
A437: 436
A438: 437
A439: 438
A440: 439
A441: 440
A442: 441
A443: 442

Sheet alamat
A1: NO | B1: NO DAFTAR | C1: NIS | D1: NAMA SISWA | E1: KELAS | F1: KET | G1: HP 1 | H1: HP 2 | I1: DUSUN | J1: RT | K1: DESA | L1: KECAMATAN | M1: ORANG TUA | N1: SMP/MTs | O1: Tgl Lahir
A2: 1 | B2: MSB25-03-353 | C2: 14741 | D2: AHMAD APRIYANTO | E2: =VLOOKUP(D2,Total!$C$2:$D$439,2,0) -> 10 RPL 1 | F2: =VLOOKUP(C2,Total!$B$2:$F$439,5,0) -> AKTIF | G2: =VLOOKUP($B2,master!$B$2:$S$595,16,0) -> 089529103240 | H2: =VLOOKUP($B2,master!$B$2:$S$595,17,0) -> 089529103240 | I2: =VLOOKUP($B2,master!$B$2:$S$595,8,0) -> MELIKAN LOR | J2: =VLOOKUP($B2,master!$B$2:$S$595,9,0) -> 005 | K2: =VLOOKUP($B2,master!$B$2:$S$595,11,0) -> BANTUL | L2: =VLOOKUP($B2,master!$B$2:$S$595,12,0) -> BANTUL | M2: =VLOOKUP($B2,master!$B$2:$S$595,6,0) -> SITI FATIMAH | N2: =VLOOKUP($B2,master!$B$2:$S$595,15,0) -> SMP N 2 BANTUL | O2: =VLOOKUP($B2,master!$B$2:$S$595,4,0) -> 23-04-2009
A3: 2 | B3: MSB25-00-045 | C3: 14742 | D3: AJI SAKA PRATAMA | E3: =VLOOKUP(D3,Total!$C$2:$D$439,2,0) -> 10 RPL 1 | F3: =VLOOKUP(C3,Total!$B$2:$F$439,5,0) -> AKTIF | G3: =VLOOKUP($B3,master!$B$2:$S$595,16,0) -> 085664315830 | H3: =VLOOKUP($B3,master!$B$2:$S$595,17,0) -> 0 | I3: =VLOOKUP($B3,master!$B$2:$S$595,8,0) -> DEPOK | J3: =VLOOKUP($B3,master!$B$2:$S$595,9,0) -> 2 | K3: =VLOOKUP($B3,master!$B$2:$S$595,11,0) -> BANTUL | L3: =VLOOKUP($B3,master!$B$2:$S$595,12,0) -> BANTUL | M3: =VLOOKUP($B3,master!$B$2:$S$595,6,0) -> IRHAN | N3: =VLOOKUP($B3,master!$B$2:$S$595,15,0) -> SMP N 32 OGAN KOMERING ULU | O3: =VLOOKUP($B3,master!$B$2:$S$595,4,0) -> 29-11-2009
A4: 3 | B4: MSB25-03-402 | C4: 14743 | D4: ALVEYRO JANNY GRACIO | E4: =VLOOKUP(D4,Total!$C$2:$D$439,2,0) -> 10 RPL 1 | F4: =VLOOKUP(C4,Total!$B$2:$F$439,5,0) -> AKTIF | G4: =VLOOKUP($B4,master!$B$2:$S$595,16,0) -> 087828484009 | H4: =VLOOKUP($B4,master!$B$2:$S$595,17,0) -> 082227750057 | I4: =VLOOKUP($B4,master!$B$2:$S$595,8,0) -> KARANGGAYAM | J4: =VLOOKUP($B4,master!$B$2:$S$595,9,0) -> 6 | K4: =VLOOKUP($B4,master!$B$2:$S$595,11,0) -> BANTUL | L4: =VLOOKUP($B4,master!$B$2:$S$595,12,0) -> BANTUL | M4: =VLOOKUP($B4,master!$B$2:$S$595,6,0) -> JANI TRI HARTANTO | N4: =VLOOKUP($B4,master!$B$2:$S$595,15,0) -> MTS N 4 BANTUL | O4: =VLOOKUP($B4,master!$B$2:$S$595,4,0) -> 12-03-2010
A5: 4 | B5: MSB25-04-572 | C5: 14744 | D5: ALYA FADMA DINATA | E5: =VLOOKUP(D5,Total!$C$2:$D$439,2,0) -> 10 RPL 1 | F5: =VLOOKUP(C5,Total!$B$2:$F$439,5,0) -> AKTIF | G5: =VLOOKUP($B5,master!$B$2:$S$595,16,0) -> 089649000989 | H5: =VLOOKUP($B5,master!$B$2:$S$595,17,0) -> 08999346532 | I5: =VLOOKUP($B5,master!$B$2:$S$595,8,0) -> KWENI | J5: =VLOOKUP($B5,master!$B$2:$S$595,9,0) -> 07 | K5: =VLOOKUP($B5,master!$B$2:$S$595,11,0) -> PANGGUNGHARJO | L5: =VLOOKUP($B5,master!$B$2:$S$595,12,0) -> SEWON | M5: =VLOOKUP($B5,master!$B$2:$S$595,6,0) -> MURJIYONO | N5: =VLOOKUP($B5,master!$B$2:$S$595,15,0) -> SMP N 4 SEWON | O5: =VLOOKUP($B5,master!$B$2:$S$595,4,0) -> 8-07-2009
A6: 5 | B6: MSB25-03-314 | C6: 14745 | D6: ANDINI REGINA ARDIYANTI | E6: =VLOOKUP(D6,Total!$C$2:$D$439,2,0) -> 10 RPL 1 | F6: =VLOOKUP(C6,Total!$B$2:$F$439,5,0) -> AKTIF | G6: =VLOOKUP($B6,master!$B$2:$S$595,16,0) -> 082330859929 | H6: =VLOOKUP($B6,master!$B$2:$S$595,17,0) -> 0888902876331 | I6: =VLOOKUP($B6,master!$B$2:$S$595,8,0) -> DIRO | J6: =VLOOKUP($B6,master!$B$2:$S$595,9,0) -> 58 | K6: =VLOOKUP($B6,master!$B$2:$S$595,11,0) -> PENDOWOHARJO | L6: =VLOOKUP($B6,master!$B$2:$S$595,12,0) -> SEWON | M6: =VLOOKUP($B6,master!$B$2:$S$595,6,0) -> SUMIJO | N6: =VLOOKUP($B6,master!$B$2:$S$595,15,0) -> SMP MUHAMMADIYAH KASIHAN | O6: =VLOOKUP($B6,master!$B$2:$S$595,4,0) -> 1-09-2009
A7: 6 | B7: MSB25-04-567 | C7: 14746 | D7: ARKHA ARDAN PRATAMA | E7: =VLOOKUP(D7,Total!$C$2:$D$439,2,0) -> 10 RPL 1 | F7: =VLOOKUP(C7,Total!$B$2:$F$439,5,0) -> AKTIF | G7: =VLOOKUP($B7,master!$B$2:$S$595,16,0) -> 081393613004 | H7: =VLOOKUP($B7,master!$B$2:$S$595,17,0) -> 0882008133270 | I7: =VLOOKUP($B7,master!$B$2:$S$595,8,0) -> KLATAK | J7: =VLOOKUP($B7,master!$B$2:$S$595,9,0) -> 01 | K7: =VLOOKUP($B7,master!$B$2:$S$595,11,0) -> GADINGSARI | L7: =VLOOKUP($B7,master!$B$2:$S$595,12,0) -> SANDEN | M7: =VLOOKUP($B7,master!$B$2:$S$595,6,0) -> ANNA LESTIYANINGSIH | N7: =VLOOKUP($B7,master!$B$2:$S$595,15,0) -> SMP N 2 PANDAK | O7: =VLOOKUP($B7,master!$B$2:$S$595,4,0) -> 23-07-2010
A8: 7 | B8: MSB25-03-358 | C8: 14747 | D8: CHELSYA RIZTI | E8: =VLOOKUP(D8,Total!$C$2:$D$439,2,0) -> 10 RPL 1 | F8: =VLOOKUP(C8,Total!$B$2:$F$439,5,0) -> AKTIF | G8: =VLOOKUP($B8,master!$B$2:$S$595,16,0) -> 08226098194 | H8: =VLOOKUP($B8,master!$B$2:$S$595,17,0) -> 083898671034 | I8: =VLOOKUP($B8,master!$B$2:$S$595,8,0) -> TEGAL KRAPYAK | J8: =VLOOKUP($B8,master!$B$2:$S$595,9,0) -> 1 | K8: =VLOOKUP($B8,master!$B$2:$S$595,11,0) -> PANGGUNGHARJO | L8: =VLOOKUP($B8,master!$B$2:$S$595,12,0) -> SEWON | M8: =VLOOKUP($B8,master!$B$2:$S$595,6,0) -> M. Rizal Wahyudi | N8: =VLOOKUP($B8,master!$B$2:$S$595,15,0) -> MTS N 2 INDRAGIRI HILIR | O8: =VLOOKUP($B8,master!$B$2:$S$595,4,0) -> 4-01-2010
A9: 8 | B9: MSB25-04-605 | C9: 14748 | D9: DONI PRATAMA | E9: =VLOOKUP(D9,Total!$C$2:$D$439,2,0) -> 10 RPL 1 | F9: =VLOOKUP(C9,Total!$B$2:$F$439,5,0) -> AKTIF | G9: =VLOOKUP($B9,master!$B$2:$S$595,16,0) -> 081999901059 | H9: =VLOOKUP($B9,master!$B$2:$S$595,17,0) -> 081999901059 | I9: =VLOOKUP($B9,master!$B$2:$S$595,8,0) -> PECIRO | J9: =VLOOKUP($B9,master!$B$2:$S$595,9,0) -> 2 | K9: =VLOOKUP($B9,master!$B$2:$S$595,11,0) -> MURTIGADING | L9: =VLOOKUP($B9,master!$B$2:$S$595,12,0) -> SANDEN | M9: =VLOOKUP($B9,master!$B$2:$S$595,6,0) -> SUDARYANTO | N9: =VLOOKUP($B9,master!$B$2:$S$595,15,0) -> MTS AL IHSAN | O9: =VLOOKUP($B9,master!$B$2:$S$595,4,0) -> 8-10-2009
A10: 9 | B10: MSB25-02-240 | C10: 14749 | D10: DZAKY ARRAHMAN | E10: =VLOOKUP(D10,Total!$C$2:$D$439,2,0) -> 10 RPL 1 | F10: =VLOOKUP(C10,Total!$B$2:$F$439,5,0) -> AKTIF | G10: =VLOOKUP($B10,master!$B$2:$S$595,16,0) -> 081224722212 | H10: =VLOOKUP($B10,master!$B$2:$S$595,17,0) -> 088227288627 | I10: =VLOOKUP($B10,master!$B$2:$S$595,8,0) -> SELO | J10: =VLOOKUP($B10,master!$B$2:$S$595,9,0) -> 1 | K10: =VLOOKUP($B10,master!$B$2:$S$595,11,0) -> SIDOMULYO | L10: =VLOOKUP($B10,master!$B$2:$S$595,12,0) -> BAMBANGLIPURO | M10: =VLOOKUP($B10,master!$B$2:$S$595,6,0) -> SARDJIMAN | N10: =VLOOKUP($B10,master!$B$2:$S$595,15,0) -> SMP N 1 BAMBANGLIPURO | O10: =VLOOKUP($B10,master!$B$2:$S$595,4,0) -> 26-11-2009
A11: 10 | B11: MSB25-03-485 | C11: 14750 | D11: ERLIENDHA PUTRI ELYSHA | E11: =VLOOKUP(D11,Total!$C$2:$D$439,2,0) -> 10 RPL 1 | F11: =VLOOKUP(C11,Total!$B$2:$F$439,5,0) -> AKTIF | G11: =VLOOKUP($B11,master!$B$2:$S$595,16,0) -> 088227697511 | H11: =VLOOKUP($B11,master!$B$2:$S$595,17,0) -> 0882006702312 | I11: =VLOOKUP($B11,master!$B$2:$S$595,8,0) -> MANDING | J11: =VLOOKUP($B11,master!$B$2:$S$595,9,0) -> 08 | K11: =VLOOKUP($B11,master!$B$2:$S$595,11,0) -> TRIRENGGO | L11: =VLOOKUP($B11,master!$B$2:$S$595,12,0) -> BANTUL | M11: =VLOOKUP($B11,master!$B$2:$S$595,6,0) -> RIRIN HARIANY | N11: =VLOOKUP($B11,master!$B$2:$S$595,15,0) -> SMP N 3 BANTUL | O11: =VLOOKUP($B11,master!$B$2:$S$595,4,0) -> 25-12-2009
A12: 11 | B12: MSB25-03-463 | C12: 14751 | D12: EVAN PERDANA PUTRA | E12: =VLOOKUP(D12,Total!$C$2:$D$439,2,0) -> 10 RPL 1 | F12: =VLOOKUP(C12,Total!$B$2:$F$439,5,0) -> AKTIF | G12: =VLOOKUP($B12,master!$B$2:$S$595,16,0) -> 085727256311 | H12: =VLOOKUP($B12,master!$B$2:$S$595,17,0) -> 085727256311 | I12: =VLOOKUP($B12,master!$B$2:$S$595,8,0) -> KARANGTALUN | J12: =VLOOKUP($B12,master!$B$2:$S$595,9,0) -> 08 | K12: =VLOOKUP($B12,master!$B$2:$S$595,11,0) -> WUKIRSARI | L12: =VLOOKUP($B12,master!$B$2:$S$595,12,0) -> IMOGIRI | M12: =VLOOKUP($B12,master!$B$2:$S$595,6,0) -> JAIMAN | N12: =VLOOKUP($B12,master!$B$2:$S$595,15,0) -> SMP N 1 IMOGIRI | O12: =VLOOKUP($B12,master!$B$2:$S$595,4,0) -> 17-01-2008
A13: 12 | B13: MSB25-03-285 | C13: 14752 | D13: FATIHUL IHSAN PUTRA SETIAWAN | E13: =VLOOKUP(D13,Total!$C$2:$D$439,2,0) -> 10 RPL 1 | F13: =VLOOKUP(C13,Total!$B$2:$F$439,5,0) -> AKTIF | G13: =VLOOKUP($B13,master!$B$2:$S$595,16,0) -> 087774777776 | H13: =VLOOKUP($B13,master!$B$2:$S$595,17,0) -> 081390592350 | I13: =VLOOKUP($B13,master!$B$2:$S$595,8,0) -> JAGAN | J13: =VLOOKUP($B13,master!$B$2:$S$595,9,0) -> 04 | K13: =VLOOKUP($B13,master!$B$2:$S$595,11,0) -> BANGUNJIWO | L13: =VLOOKUP($B13,master!$B$2:$S$595,12,0) -> KASIHAN | M13: =VLOOKUP($B13,master!$B$2:$S$595,6,0) -> Aris Setiawan | N13: =VLOOKUP($B13,master!$B$2:$S$595,15,0) -> SMP MUHAMMADIYAH BANTUL | O13: =VLOOKUP($B13,master!$B$2:$S$595,4,0) -> 14-03-2009
... A434: 433 | B434: MSB25-04-612 | C434: 14807 | D434: DOKKA UMAROV ABDURAHMAN | E434: =VLOOKUP(D434,Total!$C$2:$D$439,2,0) -> 10 TKR 2 | F434: =VLOOKUP(C434,Total!$B$2:$F$439,5,0) -> AKTIF | G434: =VLOOKUP($B434,master!$B$2:$S$595,16,0) -> 085600966783 | H434: =VLOOKUP($B434,master!$B$2:$S$595,17,0) -> 085720112959 | I434: =VLOOKUP($B434,master!$B$2:$S$595,8,0) -> KALISONO | J434: =VLOOKUP($B434,master!$B$2:$S$595,9,0) -> 12 | K434: =VLOOKUP($B434,master!$B$2:$S$595,11,0) -> TUKSONO | L434: =VLOOKUP($B434,master!$B$2:$S$595,12,0) -> SENTOLO | M434: =VLOOKUP($B434,master!$B$2:$S$595,6,0) -> HARJITO | N434: =VLOOKUP($B434,master!$B$2:$S$595,15,0) -> SMP MUHAMMADIYAH 2 LENDAH | O434: =VLOOKUP($B434,master!$B$2:$S$595,4,0) -> 9-10-2009
A435: 434 | E435: =VLOOKUP(D435,Total!$C$2:$D$439,2,0) -> #N/A | F435: =VLOOKUP(C435,Total!$B$2:$F$439,5,0) -> #N/A | G435: =VLOOKUP($B435,master!$B$2:$S$595,16,0) -> #N/A | H435: =VLOOKUP($B435,master!$B$2:$S$595,17,0) -> #N/A | I435: =VLOOKUP($B435,master!$B$2:$S$595,8,0) -> #N/A | J435: =VLOOKUP($B435,master!$B$2:$S$595,9,0) -> #N/A | K435: =VLOOKUP($B435,master!$B$2:$S$595,11,0) -> #N/A | L435: =VLOOKUP($B435,master!$B$2:$S$595,12,0) -> #N/A | M435: =VLOOKUP($B435,master!$B$2:$S$595,6,0) -> #N/A | N435: =VLOOKUP($B435,master!$B$2:$S$595,15,0) -> #N/A | O435: =VLOOKUP($B435,master!$B$2:$S$595,4,0) -> #N/A
A436: 435 | E436: =VLOOKUP(D436,Total!$C$2:$D$439,2,0) -> #N/A | F436: =VLOOKUP(C436,Total!$B$2:$F$439,5,0) -> #N/A | G436: =VLOOKUP($B436,master!$B$2:$S$595,16,0) -> #N/A | H436: =VLOOKUP($B436,master!$B$2:$S$595,17,0) -> #N/A | I436: =VLOOKUP($B436,master!$B$2:$S$595,8,0) -> #N/A | J436: =VLOOKUP($B436,master!$B$2:$S$595,9,0) -> #N/A | K436: =VLOOKUP($B436,master!$B$2:$S$595,11,0) -> #N/A | L436: =VLOOKUP($B436,master!$B$2:$S$595,12,0) -> #N/A | M436: =VLOOKUP($B436,master!$B$2:$S$595,6,0) -> #N/A | N436: =VLOOKUP($B436,master!$B$2:$S$595,15,0) -> #N/A | O436: =VLOOKUP($B436,master!$B$2:$S$595,4,0) -> #N/A
A437: 436 | E437: =VLOOKUP(D437,Total!$C$2:$D$439,2,0) -> #N/A | F437: =VLOOKUP(C437,Total!$B$2:$F$439,5,0) -> #N/A | G437: =VLOOKUP($B437,master!$B$2:$S$595,16,0) -> #N/A | H437: =VLOOKUP($B437,master!$B$2:$S$595,17,0) -> #N/A | I437: =VLOOKUP($B437,master!$B$2:$S$595,8,0) -> #N/A | J437: =VLOOKUP($B437,master!$B$2:$S$595,9,0) -> #N/A | K437: =VLOOKUP($B437,master!$B$2:$S$595,11,0) -> #N/A | L437: =VLOOKUP($B437,master!$B$2:$S$595,12,0) -> #N/A | M437: =VLOOKUP($B437,master!$B$2:$S$595,6,0) -> #N/A | N437: =VLOOKUP($B437,master!$B$2:$S$595,15,0) -> #N/A | O437: =VLOOKUP($B437,master!$B$2:$S$595,4,0) -> #N/A
A438: 437 | E438: =VLOOKUP(D438,Total!$C$2:$D$439,2,0) -> #N/A | F438: =VLOOKUP(C438,Total!$B$2:$F$439,5,0) -> #N/A | G438: =VLOOKUP($B438,master!$B$2:$S$595,16,0) -> #N/A | H438: =VLOOKUP($B438,master!$B$2:$S$595,17,0) -> #N/A | I438: =VLOOKUP($B438,master!$B$2:$S$595,8,0) -> #N/A | J438: =VLOOKUP($B438,master!$B$2:$S$595,9,0) -> #N/A | K438: =VLOOKUP($B438,master!$B$2:$S$595,11,0) -> #N/A | L438: =VLOOKUP($B438,master!$B$2:$S$595,12,0) -> #N/A | M438: =VLOOKUP($B438,master!$B$2:$S$595,6,0) -> #N/A | N438: =VLOOKUP($B438,master!$B$2:$S$595,15,0) -> #N/A | O438: =VLOOKUP($B438,master!$B$2:$S$595,4,0) -> #N/A
A439: 438 | E439: =VLOOKUP(D439,Total!$C$2:$D$439,2,0) -> #N/A | F439: =VLOOKUP(C439,Total!$B$2:$F$439,5,0) -> #N/A | G439: =VLOOKUP($B439,master!$B$2:$S$595,16,0) -> #N/A | H439: =VLOOKUP($B439,master!$B$2:$S$595,17,0) -> #N/A | I439: =VLOOKUP($B439,master!$B$2:$S$595,8,0) -> #N/A | J439: =VLOOKUP($B439,master!$B$2:$S$595,9,0) -> #N/A | K439: =VLOOKUP($B439,master!$B$2:$S$595,11,0) -> #N/A | L439: =VLOOKUP($B439,master!$B$2:$S$595,12,0) -> #N/A | M439: =VLOOKUP($B439,master!$B$2:$S$595,6,0) -> #N/A | N439: =VLOOKUP($B439,master!$B$2:$S$595,15,0) -> #N/A | O439: =VLOOKUP($B439,master!$B$2:$S$595,4,0) -> #N/A
A440: 439 | E440: =VLOOKUP(D440,Total!$C$2:$D$439,2,0) -> #N/A | F440: =VLOOKUP(C440,Total!$B$2:$F$439,5,0) -> #N/A | G440: =VLOOKUP($B440,master!$B$2:$S$595,16,0) -> #N/A | H440: =VLOOKUP($B440,master!$B$2:$S$595,17,0) -> #N/A | I440: =VLOOKUP($B440,master!$B$2:$S$595,8,0) -> #N/A | J440: =VLOOKUP($B440,master!$B$2:$S$595,9,0) -> #N/A | K440: =VLOOKUP($B440,master!$B$2:$S$595,11,0) -> #N/A | L440: =VLOOKUP($B440,master!$B$2:$S$595,12,0) -> #N/A | M440: =VLOOKUP($B440,master!$B$2:$S$595,6,0) -> #N/A | N440: =VLOOKUP($B440,master!$B$2:$S$595,15,0) -> #N/A | O440: =VLOOKUP($B440,master!$B$2:$S$595,4,0) -> #N/A
A441: 440 | E441: =VLOOKUP(D441,Total!$C$2:$D$439,2,0) -> #N/A | F441: =VLOOKUP(C441,Total!$B$2:$F$439,5,0) -> #N/A | G441: =VLOOKUP($B441,master!$B$2:$S$595,16,0) -> #N/A | H441: =VLOOKUP($B441,master!$B$2:$S$595,17,0) -> #N/A | I441: =VLOOKUP($B441,master!$B$2:$S$595,8,0) -> #N/A | J441: =VLOOKUP($B441,master!$B$2:$S$595,9,0) -> #N/A | K441: =VLOOKUP($B441,master!$B$2:$S$595,11,0) -> #N/A | L441: =VLOOKUP($B441,master!$B$2:$S$595,12,0) -> #N/A | M441: =VLOOKUP($B441,master!$B$2:$S$595,6,0) -> #N/A | N441: =VLOOKUP($B441,master!$B$2:$S$595,15,0) -> #N/A | O441: =VLOOKUP($B441,master!$B$2:$S$595,4,0) -> #N/A
A442: 441 | E442: =VLOOKUP(D442,Total!$C$2:$D$439,2,0) -> #N/A | F442: =VLOOKUP(C442,Total!$B$2:$F$439,5,0) -> #N/A | G442: =VLOOKUP($B442,master!$B$2:$S$595,16,0) -> #N/A | H442: =VLOOKUP($B442,master!$B$2:$S$595,17,0) -> #N/A | I442: =VLOOKUP($B442,master!$B$2:$S$595,8,0) -> #N/A | J442: =VLOOKUP($B442,master!$B$2:$S$595,9,0) -> #N/A | K442: =VLOOKUP($B442,master!$B$2:$S$595,11,0) -> #N/A | L442: =VLOOKUP($B442,master!$B$2:$S$595,12,0) -> #N/A | M442: =VLOOKUP($B442,master!$B$2:$S$595,6,0) -> #N/A | N442: =VLOOKUP($B442,master!$B$2:$S$595,15,0) -> #N/A | O442: =VLOOKUP($B442,master!$B$2:$S$595,4,0) -> #N/A
A443: 442 | E443: =VLOOKUP(D443,Total!$C$2:$D$439,2,0) -> #N/A | F443: =VLOOKUP(C443,Total!$B$2:$F$439,5,0) -> #N/A | G443: =VLOOKUP($B443,master!$B$2:$S$595,16,0) -> #N/A | H443: =VLOOKUP($B443,master!$B$2:$S$595,17,0) -> #N/A | I443: =VLOOKUP($B443,master!$B$2:$S$595,8,0) -> #N/A | J443: =VLOOKUP($B443,master!$B$2:$S$595,9,0) -> #N/A | K443: =VLOOKUP($B443,master!$B$2:$S$595,11,0) -> #N/A | L443: =VLOOKUP($B443,master!$B$2:$S$595,12,0) -> #N/A | M443: =VLOOKUP($B443,master!$B$2:$S$595,6,0) -> #N/A | N443: =VLOOKUP($B443,master!$B$2:$S$595,15,0) -> #N/A | O443: =VLOOKUP($B443,master!$B$2:$S$595,4,0) -> #N/A
A444: 443 | E444: =VLOOKUP(D444,Total!$C$2:$D$439,2,0) -> #N/A | F444: =VLOOKUP(C444,Total!$B$2:$F$439,5,0) -> #N/A | G444: =VLOOKUP($B444,master!$B$2:$S$595,16,0) -> #N/A | H444: =VLOOKUP($B444,master!$B$2:$S$595,17,0) -> #N/A | I444: =VLOOKUP($B444,master!$B$2:$S$595,8,0) -> #N/A | J444: =VLOOKUP($B444,master!$B$2:$S$595,9,0) -> #N/A | K444: =VLOOKUP($B444,master!$B$2:$S$595,11,0) -> #N/A | L444: =VLOOKUP($B444,master!$B$2:$S$595,12,0) -> #N/A | M444: =VLOOKUP($B444,master!$B$2:$S$595,6,0) -> #N/A | N444: =VLOOKUP($B444,master!$B$2:$S$595,15,0) -> #N/A | O444: =VLOOKUP($B444,master!$B$2:$S$595,4,0) -> #N/A
A445: 444 | E445: =VLOOKUP(D445,Total!$C$2:$D$439,2,0) -> #N/A | F445: =VLOOKUP(C445,Total!$B$2:$F$439,5,0) -> #N/A | G445: =VLOOKUP($B445,master!$B$2:$S$595,16,0) -> #N/A | H445: =VLOOKUP($B445,master!$B$2:$S$595,17,0) -> #N/A | I445: =VLOOKUP($B445,master!$B$2:$S$595,8,0) -> #N/A | J445: =VLOOKUP($B445,master!$B$2:$S$595,9,0) -> #N/A | K445: =VLOOKUP($B445,master!$B$2:$S$595,11,0) -> #N/A | L445: =VLOOKUP($B445,master!$B$2:$S$595,12,0) -> #N/A | M445: =VLOOKUP($B445,master!$B$2:$S$595,6,0) -> #N/A | N445: =VLOOKUP($B445,master!$B$2:$S$595,15,0) -> #N/A | O445: =VLOOKUP($B445,master!$B$2:$S$595,4,0) -> #N/A
A446: 445 | E446: =VLOOKUP(D446,Total!$C$2:$D$439,2,0) -> #N/A | F446: =VLOOKUP(C446,Total!$B$2:$F$439,5,0) -> #N/A | G446: =VLOOKUP($B446,master!$B$2:$S$595,16,0) -> #N/A | H446: =VLOOKUP($B446,master!$B$2:$S$595,17,0) -> #N/A | I446: =VLOOKUP($B446,master!$B$2:$S$595,8,0) -> #N/A | J446: =VLOOKUP($B446,master!$B$2:$S$595,9,0) -> #N/A | K446: =VLOOKUP($B446,master!$B$2:$S$595,11,0) -> #N/A | L446: =VLOOKUP($B446,master!$B$2:$S$595,12,0) -> #N/A | M446: =VLOOKUP($B446,master!$B$2:$S$595,6,0) -> #N/A | N446: =VLOOKUP($B446,master!$B$2:$S$595,15,0) -> #N/A | O446: =VLOOKUP($B446,master!$B$2:$S$595,4,0) -> #N/A

Sheet master
A1: No | B1: Nomor Pendaftaran | C1: Nama Lengkap | D1: Tempat Lahir | E1: Tangal Lahir Siswa | F1: JeKel | G1: Nama Ortu | H1: Pekerjaan Ortu | I1: Dusun | J1: RT | K1: RW | L1: Kelurahan | M1: Kecamatan | N1: Kabupaten | O1: Prov | P1: Asal Sekolah | Q1: No Siswa | R1: No Ortu | S1: Pil 1
A2: 1 | B2: MSB25-00-001 | C2: FERISCHO RICKY SAPUTRA | D2: BANTUL | E2: 7-03-2010 | F2: L | G2: RUDIYANTO | H2: KARYAWAN SWASTA | I2: KEPUH | J2: 3 | K2: 0 | L2: MULYODADI | M2: BAMBANGLIPURO | N2: BANTUL | O2: DIY | P2: SMP MUHAMMADIYAH 1 BAMBANGLIPURO | Q2: 083113003554 | S2: TBSM
A3: 2 | B3: MSB25-00-002 | C3: AFGA DWI CAHYO | D3: BANTUL | E3: 28-08-2010 | F3: L | G3: SUGIWIYANA | H3: PETANI | I3: PALIHAN | J3: 3 | K3: 0 | L3: SIDOMULYO | M3: BAMBANGLIPURO | N3: BANTUL | O3: DIY | P3: SMP N 1 BAMBANGLIPURO | Q3: 087804842540 | S3: TBSM
A4: 3 | B4: MSB25-00-003 | C4: DWI RIZIQI NUGROHO | D4: BANTUL | E4: 20-03-2010 | F4: L | G4: MUDAKIR | H4: buruh | I4: PELEMSEWU | J4: 5 | K4: 0 | L4: PANGGUNGHARJO | M4: SEWON | N4: BANTUL | O4: DIY | P4: SMP MUHAMMADIYAH SEWON | Q4: 08972189566 | S4: TKR
A5: 4 | B5: MSB25-00-004 | C5: ARFIYAN RIZKY KURNIAWAN | D5: BANTUL | E5: 20-11-2009 | F5: L | G5: ARIYONO | H5: BURUH | I5: BOLON | J5: 4 | K5: 0 | L5: PALBAPANG | M5: BANTUL | N5: BANTUL | O5: DIY | P5: SMP N 3 BANTUL | Q5: 085713331085 | S5: TBSM
A6: 5 | B6: MSB25-00-005 | C6: RIFQI ILHAM PRATAMA | D6: BANTUL | E6: 13-03-2010 | F6: L | G6: RINTOKO | H6: BURUH | I6: MONGGANG | J6: 6 | K6: 0 | L6: SRIHARDONO | M6: PUNDONG | N6: BANTUL | O6: DIY | P6: SMP N 1 PUNDONG | Q6: 085759121667 | S6: TKR
A7: 6 | B7: MSB25-00-006 | C7: FAHRIZAL TEGAR DWI SANTOSO | D7: BANTUL | E7: 9-03-2010 | F7: L | G7: PURWADI SANTOSO | H7: BURUH | I7: KADIBESO | J7: 3 | K7: 0 | L7: SABDODADI | M7: BANTUL | N7: BANTUL | O7: DIY | P7: SMP N 3 BANTUL | Q7: 087839467341 | S7: TBSM
A8: 7 | B8: MSB25-00-007 | C8: BAHRUL ULUM NAFI | D8: BANTUL | E8: 11-01-2010 | F8: L | G8: SUGIONO | H8: JUALAN | I8: PEPE | J8: 1 | L8: TRIRENGGO | M8: BANTUL | N8: BANTUL | O8: DIY | P8: SMP PANCASILA KRIAN | Q8: 085732030340 | S8: TKR
A9: 8 | B9: MSB25-00-008 | C9: RAKA DWI ANDIKA | D9: BANTUL | E9: 4-06-2009 | F9: L | G9: NURYADI | H9: BURUH | I9: KRAPYAK KULON | J9: 1 | K9: 0 | L9: PANGGUNGHARJO | M9: SEWON | N9: BANTUL | O9: DIY | P9: SMP N 4 SEWON | Q9: 081359510458 | S9: TKR
A10: 9 | B10: MSB25-00-009 | C10: DIMAS PUTRA PRATAMA | D10: BANTUL | E10: 8-07-2009 | F10: L | G10: SLAMET | H10: BURUH | I10: PANJANG | J10: 2 | K10: 0 | L10: PANJANGREJO | M10: PUNDONG | N10: BANTUL | O10: DIY | P10: SMP N 1 PUNDONG | Q10: 08995080974 | S10: TKR
A11: 10 | B11: MSB25-00-010 | C11: MUHAMMAD ALIF ERFANURDIANSYAH | D11: BANTUL | E11: 21-09-2009 | F11: L | G11: KUN FAYADI | H11: BURUH | I11: CEPOR KIDUL | J11: 5 | K11: 0 | L11: PALBAPANG | M11: BANTUL | N11: BANTUL | O11: DIY | P11: SMP MUHAMMADIYAH 2 BAMBANGLIPURO | Q11: 085727740015 | S11: TBSM
A12: 11 | B12: MSB25-00-011 | C12: GALANG FIRMAN SAPUTRA | D12: BANTUL | E12: 7-01-2010 | F12: L | G12: GUNARDI | H12: BURUH | I12: CEPOR KIDUL | J12: 5 | K12: 0 | L12: PALBAPANG | M12: BANTUL | N12: BANTUL | O12: DIY | P12: SMP N 3 BANTUL | Q12: 087838738900 | S12: TBSM
A13: 12 | B13: MSB25-00-012 | C13: BIMO FAJAR KUSUMA | D13: BANTUL | E13: 31-03-2010 | F13: L | G13: TUKIJAN | H13: BURUH | I13: MANDING | J13: 3 | K13: 0 | L13: SABDODADI | M13: BANTUL | N13: BANTUL | O13: DIY | P13: SMP MUHAMMADIYAH BANTUL | Q13: 0895325667873 | S13: TBSM
A14: 13 | B14: MSB25-00-013 | C14: AGUS DWI RIYANTO | D14: BANTUL | E14: 15-08-2008 | F14: L | G14: MURDIMAN | H14: BURUH | I14: GANDEKAN | J14: 1 | K14: 0 | L14: TRIRENGGO | M14: BANTUL | N14: BANTUL | O14: DIY | P14: SMP ISLAM PRESTASI | Q14: 089504591520 | S14: TKR
A15: 14 | B15: MSB25-00-014 | C15: SATRIA RAKA ADE PRASETYO | D15: BANTUL | E15: 24-01-2010 | F15: L | G15: KIRWANTO | H15: BURUH | I15: DAGEN | J15: 4 | K15: 0 | L15: RINGIN HARJO | M15: BANTUL | N15: BANTUL | O15: DIY | P15: SMP MUHAMMADIYAH BANTUL | Q15: 083846731305 | S15: TPM
A16: 15 | B16: MSB25-00-015 | C16: KANE SAVERO RIDHO YULIANTO | D16: BANTUL | E16: 13-10-2009 | F16: L | G16: AGUS YULIANTO | H16: WIRASWASTA | I16: KARASAN | J16: 2 | K16: 0 | L16: PALBAPANG | M16: BANTUL | N16: BANTUL | O16: DIY | P16: SMP N 1 BAMBANGLIPURO | Q16: 082223236576 | S16: TPM
A17: 16 | B17: MSB25-00-016 | C17: HURIN NA'IMAH | D17: BANTUL | E17: 7-01-2010 | F17: P | G17: ABDUL HAMID | H17: BURUH | I17: JODOG | J17: 5 | K17: 0 | L17: GILANGHARJO | M17: PANDAK | N17: BANTUL | O17: DIY | P17: SMP N 3 PANDAK | Q17: 085712643658 | S17: TKR
A18: 17 | B18: MSB25-00-017 | C18: MUHAMMAD ABBAD ADZ DZAKA | D18: GRESIK | E18: 3-01-2010 | F18: L | G18: SUTARDI | H18: WIRASWASTA | I18: KLEMBON | J18: 4 | K18: 0 | L18: TRIRENGGO | M18: BANTUL | N18: BANTUL | O18: DIY | P18: MTs N 4 BANTUL | Q18: 087846631667 | S18: TBSM
A19: 18 | B19: MSB25-00-018 | C19: FAUZ EGA RAMADHAN | D19: BANTUL | E19: 12-09-2009 | F19: L | G19: PONIDI | H19: BURUH | I19: SOKA | J19: 1 | K19: 0 | L19: SELOHARJO | M19: PUNDONG | N19: BANTUL | O19: DIY | P19: SMP N 1 PUNDONG | Q19: 085640939299 | S19: TBSM
A20: 19 | B20: MSB25-00-019 | C20: RAFAEL RIVIANSYAH | D20: BANTUL | E20: 26-07-2009 | F20: L | G20: RISYANTO | H20: BURUH | I20: MASAHAN | J20: 3 | K20: 0 | L20: TRIRENGGO | M20: BANTUL | N20: BANTUL | O20: DIY | P20: SMP N 3 BANTUL | Q20: 085700549872 | S20: TBSM
... A45: 44 | B45: MSB25-00-044 | C45: RAFKA ANDARA PRADANA | D45: BANTUL | E45: 2-08-2009 | F45: L | G45: SRI SUTRISNI | H45: BURUH | I45: NOGOSARI, KREKAH | J45: 8 | K45: 0 | L45: GILANGHARJO | M45: PANDAK | N45: BANTUL | O45: DIY | P45: SMP N 4 PANDAK | Q45: 087738504843 | S45: TBSM
A46: 45 | B46: MSB25-00-045 | C46: AJI SAKA PRATAMA | D46: SEKAMPUNG | E46: 29-11-2009 | F46: L | G46: IRHAN | H46: IRT | I46: DEPOK | J46: 2 | L46: BANTUL | M46: BANTUL | N46: BANTUL | O46: DIY | P46: SMP N 32 OGAN KOMERING ULU | Q46: 085664315830 | S46: RPL
A47: 46 | B47: MSB25-00-046 | C47: ADRIAN REZKY SAPUTRA | D47: BANTUL | E47: 1-11-2009 | F47: L | G47: HARWADI | H47: BURUH | I47: GEDONGAN | J47: 6 | K47: 0 | L47: BANGUNJIWO | M47: KASIHAN | N47: BANTUL | O47: DIY | P47: SMP MUHAMMADIYAH SEWON | Q47: 0895359379580 | S47: TBSM
A48: 47 | B48: MSB25-00-047 | C48: ARDELL MAHENDRA YOVAN PRAMUDITA | D48: YOGYAKARTA | E48: 20-06-2009 | F48: L | G48: WAWAN PRAMUDI | H48: PERCETAKAN | I48: SEMAIL | J48: 1 | K48: 0 | L48: BANGUNHARJO | M48: SEWON | N48: BANTUL | O48: DIY | P48: SMP MUHAMMADIYAH 9 YOGYAKARTA | Q48: 0882005445523 | S48: TBSM
A49: 48 | B49: MSB25-00-048 | C49: AHMAD HAFIZ MAULANA | D49: YOGYAKARTA | E49: 9-10-2009 | F49: L | G49: SUNARTA | H49: WIRASWASTA | I49: PASUTAN | J49: 2 | K49: 0 | L49: TRIRENGGO | M49: BANTUL | N49: BANTUL | O49: DIY | P49: SMP N 2 BANTUL | Q49: 082220545206 | S49: TBSM
A50: 49 | B50: MSB25-00-049 | C50: RAFLI ADRIANSYAH | D50: BANTUL | E50: 11-06-2009 | F50: L | G50: AGUNG BUDI SANTOSO | H50: buruh | I50: SOMPOK | J50: 6 | K50: 0 | L50: SRIHARJO | M50: IMOGIRI | N50: BANTUL | O50: DIY | P50: SMP N 3 IMOGIRI | Q50: 083104813503 | S50: TKR
