Workbook

Sheet TAV 1
M1: KUR/PPB/FO-002
M2: Rev. 02 / 15 Juli 2019
A3: DAFTAR HADIR SISWA
A4: ( CATATAN HARIAN GURU DAN DAFTAR NILAI )
A5: SMK MUHAMMADIYAH 1 BANTUL
A6: KELAS : XI TAV
A8: MATA PELAJARAN :.................................................. | L8: SEMESTER :..................
A9: GURU MATA PELAJARAN :.................................................. | L9: TAHUN PELAJARAN : 2025/2026
A10: WALI AMANAH | C10: : Dieni Nugrahini, S.Pd
A11: NOMOR | C11: NAMA | D11: BULAN : | I11: JUMLAH | L11: Nilai Tugas Harian | Q11: Nilai KD
A12: URUT | B12: INDUK | I12: S | J12: I | K12: A | L12: 1 | M12: 2 | N12: 3 | O12: 4 | P12: 5
A13: 1 | B13: 13862 | C13: AFIFAN PUTRA MUKLISHAN
A14: 2 | B14: 13864 | C14: AHMAD FALAKHUL MUTTAQI
A15: 3 | B15: 13865 | C15: ALBANI DIAN RASYID
A16: 4 | B16: 13866 | C16: ALDIANO RIZKY
A17: 5 | B17: 13867 | C17: ALFIN MAULANA PUTRA
A18: 6 | B18: 13868 | C18: ARKHAB ISLAM SUPRIYADI
A19: 7 | B19: 13869 | C19: BAGAS ALAM NURSETO
A20: 8 | B20: 13870 | C20: DAFFAZACKY NURFIANSYAH
A21: 9 | B21: 13871 | C21: DHIMAS SUNGKONO PUTRO
A22: 10 | B22: 13872 | C22: ELANGGA BAGAS AJI SAPUTRA
A23: 11 | B23: 13873 | C23: FAHRI ABDILLAH
A24: 12 | B24: 13874 | C24: FAIZZA ISNAN AFFANI
... A42: 30 | B42: 13892 | C42: ZULKARNAEN ALLIFYANSYAH
A43: 31
A44: 32
A45: 33
A46: 34
A48: CATATAN HARIAN GURU | L48: Deskripsi Penilaian
A49: NO | B49: Tanggal | C49: Kegiatan Pembelajaran | D49: Materi Pembelajaran
A50: 1 | C50: Menerangkan/Diskusi/Tugas/Ujian*) | L50: 1
A51: 2 | C51: Menerangkan/Diskusi/Tugas/Ujian*) | L51: 2
A52: 3 | C52: Menerangkan/Diskusi/Tugas/Ujian*) | L52: 3
A53: 4 | C53: Menerangkan/Diskusi/Tugas/Ujian*) | L53: 4
A54: 5 | C54: Menerangkan/Diskusi/Tugas/Ujian*) | L54: 5
A55: Keterangan : | K55: Bantul,……………………………………….
A56: Penilaian diisikan setiap kali melakukan penilaian harian berupa tugas, tes tertulis, tes lisan, tes unjuk kerja atau portopolio ( Validasi setiap Bulan ) | K56: Guru Bidang Studi
A58: *) Pada kolom kegiatan pembelajaran coret yang tidak dilakukan, kegiatan pembelajaran bisa lebih dari satu kegiatan
K59: …………………………………………….
K60: NBM…………………………………….
...

Sheet TPM 1
M1: KUR/PPB/FO-002
M2: Rev. 02 / 15 Juli 2019
A3: DAFTAR HADIR SISWA
A4: ( CATATAN HARIAN GURU DAN DAFTAR NILAI )
A5: SMK MUHAMMADIYAH 1 BANTUL
A6: KELAS : XI TPM 1
A8: MATA PELAJARAN :.................................................. | L8: SEMESTER :..................
A9: GURU MATA PELAJARAN :.................................................. | L9: TAHUN PELAJARAN : 2025/2026
A10: WALI AMANAH | C10: : Annisa Rizki Amellia, S.Pd
A11: NOMOR | C11: NAMA | D11: BULAN : | I11: JUMLAH | L11: Nilai Tugas Harian | Q11: Nilai KD
A12: URUT | B12: INDUK | I12: S | J12: I | K12: A | L12: 1 | M12: 2 | N12: 3 | O12: 4 | P12: 5
A13: 1 | B13: 13893 | C13: AFRIZAL MANSYUR
A14: 2 | B14: 13894 | C14: AHMAD ALFA RISKI
A15: 3 | B15: 13895 | C15: AHMAD MUFID MUNAWAR
A16: 4 | B16: 13896 | C16: ALAN RYNO SAPUTRA
A17: 5 | B17: 13897 | C17: ALIF NURCAHYO
A18: 6 | B18: 13898 | C18: BARA YUSUF ADRIAN
A19: 7 | B19: 13899 | C19: DAFA SURYA SAPUTRA
A20: 8 | B20: 13900 | C20: FATAN KHOLIQ APRIANO
A21: 9 | B21: 13901 | C21: FIKRI IQBAL FATHURRAHIM
A22: 10 | B22: 13902 | C22: FRIANDA DARMAWAN
A23: 11 | B23: 13903 | C23: HABIB AULIA
A24: 12 | B24: 13904 | C24: HANIF DWI MUSTAFA
... A46: 34 | B46: 13929 | C46: ZAKI KHOIRON
A47: 35
A48: 36
A49: 37
A51: CATATAN HARIAN GURU | L51: Deskripsi Penilaian
A52: NO | B52: Tanggal | C52: Kegiatan Pembelajaran | D52: Materi Pembelajaran
A53: 1 | C53: Menerangkan/Diskusi/Tugas/Ujian*) | L53: 1
A54: 2 | C54: Menerangkan/Diskusi/Tugas/Ujian*) | L54: 2
A55: 3 | C55: Menerangkan/Diskusi/Tugas/Ujian*) | L55: 3
A56: 4 | C56: Menerangkan/Diskusi/Tugas/Ujian*) | L56: 4
A57: 5 | C57: Menerangkan/Diskusi/Tugas/Ujian*) | L57: 5
A58: Keterangan : | K58: Bantul,……………………………………….
A59: Penilaian diisikan setiap kali melakukan penilaian harian berupa tugas, tes tertulis, tes lisan, tes unjuk kerja atau portopolio ( Validasi setiap Bulan ) | K59: Guru Bidang Studi
A61: *) Pada kolom kegiatan pembelajaran coret yang tidak dilakukan, kegiatan pembelajaran bisa lebih dari satu kegiatan
K62: …………………………………………….
K63: NBM…………………………………….
A65: *) 16-jun-2025

Sheet TPM 2
M1: KUR/PPB/FO-002
M2: Rev. 02 / 15 Juli 2019
A3: DAFTAR HADIR SISWA
A4: ( CATATAN HARIAN GURU DAN DAFTAR NILAI )
A5: SMK MUHAMMADIYAH 1 BANTUL
A6: KELAS : XI TPM 2
A8: MATA PELAJARAN :.................................................. | L8: SEMESTER :..................
A9: GURU MATA PELAJARAN :.................................................. | L9: TAHUN PELAJARAN : 2025/2026
A10: WALI AMANAH | C10: : Agus Haryanto, A.Md
A11: NOMOR | C11: NAMA | D11: BULAN : | I11: JUMLAH | L11: Nilai Tugas Harian | Q11: Nilai KD
A12: URUT | B12: INDUK | I12: S | J12: I | K12: A | L12: 1 | M12: 2 | N12: 3 | O12: 4 | P12: 5
A13: 1 | B13: 13930 | C13: ADITYA NOVA RESTANTO
A14: 2 | B14: 13931 | C14: AFRIAN SURYA FEBRIANSYAH
A15: 3 | B15: 13934 | C15: AKMA IKHWAN ARKHANANTA
A16: 4 | B16: 13935 | C16: ALIF GILANG SETIAWAN
A17: 5 | B17: 13937 | C17: BRAMANTYO AJI
A18: 6 | B18: 13938 | C18: DAVINKO PRAMADIKA CHRISNANDA
A19: 7 | B19: 13939 | C19: FERRY EKA SYAHPUTRA
A20: 8 | B20: 13940 | C20: HAJID NANDA RAHMAWAN
A21: 9 | B21: 13941 | C21: HEMA MAHRUBI PURNOMO
A22: 10 | B22: 13943 | C22: IVAN NUR IKHSAN
A23: 11 | B23: 13944 | C23: JUSUF TARIQ ASAKTI
A24: 12 | B24: 13945 | C24: LUCKY RAHMAT DANI
... A42: 30 | B42: 13964 | C42: YUNUZ
A43: 31
A44: 32
A45: 33
A46: 34
A47: 35
A48: 36
A50: CATATAN HARIAN GURU | L50: Deskripsi Penilaian
A51: NO | B51: Tanggal | C51: Kegiatan Pembelajaran | D51: Materi Pembelajaran
A52: 1 | C52: Menerangkan/Diskusi/Tugas/Ujian*) | L52: 1
A53: 2 | C53: Menerangkan/Diskusi/Tugas/Ujian*) | L53: 2
A54: 3 | C54: Menerangkan/Diskusi/Tugas/Ujian*) | L54: 3
A55: 4 | C55: Menerangkan/Diskusi/Tugas/Ujian*) | L55: 4
A56: 5 | C56: Menerangkan/Diskusi/Tugas/Ujian*) | L56: 5
A57: Keterangan : | K57: Bantul,……………………………………….
A58: Penilaian diisikan setiap kali melakukan penilaian harian berupa tugas, tes tertulis, tes lisan, tes unjuk kerja atau portopolio ( Validasi setiap Bulan ) | K58: Guru Bidang Studi
A60: *) Pada kolom kegiatan pembelajaran coret yang tidak dilakukan, kegiatan pembelajaran bisa lebih dari satu kegiatan
...

Sheet TKRO 1
M1: KUR/PPB/FO-002
M2: Rev. 02 / 15 Juli 2019
A3: DAFTAR HADIR SISWA
A4: ( CATATAN HARIAN GURU DAN DAFTAR NILAI )
A5: SMK MUHAMMADIYAH 1 BANTUL
A6: KELAS : XI TKR 1
A8: MATA PELAJARAN :.................................................. | L8: SEMESTER :..................
A9: GURU MATA PELAJARAN :.................................................. | L9: TAHUN PELAJARAN : 2025/2026
A10: WALI AMANAH | C10: : Muhammad Khairil Anwar, S.Pd
A11: NOMOR | C11: NAMA | D11: BULAN : | I11: JUMLAH | L11: Nilai Tugas Harian | Q11: Nilai KD
A12: URUT | B12: INDUK | I12: S | J12: I | K12: A | L12: 1 | M12: 2 | N12: 3 | O12: 4 | P12: 5
A13: 1 | B13: 13965 | C13: ABIYASA SATYA NUGRAHA
A14: 2 | B14: 13966 | C14: ADIL WIBOWO
A15: 3 | B15: 13967 | C15: AHNAF ADJIE PANGESTU
A16: 4 | B16: 13968 | C16: ALMER FAYYADH KHOIRY BASAYEV
A17: 5 | B17: 13969 | C17: ALVY SETIAWAN
A18: 6 | B18: 13970 | C18: ANDRA ANUARI PRATAMA
A19: 7 | B19: 13971 | C19: ANGGIT HANANTYA PUTRA
A20: 8 | B20: 13972 | C20: ARDIN FAUSTA ANUGRAH SAPUTRA
A21: 9 | B21: 13973 | C21: AUFA DAFA KUSUMAH ATMAJA
A22: 10 | B22: 13974 | C22: BAGUS ARIYA ADINATA
A23: 11 | B23: 13976 | C23: DEVANO RIZKY PRATAMA
A24: 12 | B24: 13977 | C24: DHIMAZ JORDAN
... A40: 28 | B40: 13998 | C40: YUDHA PRATAMA
A41: 29
A42: 30
A43: 31
A44: 32
A45: 33
A46: 34
A47: 35
A48: 36
A50: CATATAN HARIAN GURU | L50: Deskripsi Penilaian
A51: NO | B51: Tanggal | C51: Kegiatan Pembelajaran | D51: Materi Pembelajaran
A52: 1 | C52: Menerangkan/Diskusi/Tugas/Ujian*) | L52: 1
A53: 2 | C53: Menerangkan/Diskusi/Tugas/Ujian*) | L53: 2
A54: 3 | C54: Menerangkan/Diskusi/Tugas/Ujian*) | L54: 3
A55: 4 | C55: Menerangkan/Diskusi/Tugas/Ujian*) | L55: 4
A56: 5 | C56: Menerangkan/Diskusi/Tugas/Ujian*) | L56: 5
A57: Keterangan : | K57: Bantul,……………………………………….
...

Sheet TKRO 2
M1: KUR/PPB/FO-002
M2: Rev. 02 / 15 Juli 2019
A3: DAFTAR HADIR SISWA
A4: ( CATATAN HARIAN GURU DAN DAFTAR NILAI )
A5: SMK MUHAMMADIYAH 1 BANTUL
A6: KELAS : XI TKR 2
A8: MATA PELAJARAN :.................................................. | L8: SEMESTER :..................
A9: GURU MATA PELAJARAN :.................................................. | L9: TAHUN PELAJARAN : 2025/2026
A10: WALI AMANAH | C10: : Ardik Sudarmaji, S.T
A11: NOMOR | C11: NAMA | D11: BULAN : | I11: JUMLAH | L11: Nilai Tugas Harian | Q11: Nilai KD
A12: URUT | B12: INDUK | I12: S | J12: I | K12: A | L12: 1 | M12: 2 | N12: 3 | O12: 4 | P12: 5
A13: 1 | B13: 13999 | C13: ACHMAD DAFFA PUTRA SAMUDRA
A14: 2 | B14: 14000 | C14: AGHA SATRIA NUR AKBAR
A15: 3 | B15: 14001 | C15: AJISAPUTRA RIZAL EFFENDI
A16: 4 | B16: 14002 | C16: ALTAR BRAMANTYA PUTRA
A17: 5 | B17: 14003 | C17: ANDRA SAPUTRA
A18: 6 | B18: 14004 | C18: ANNAS ABDUR ROZAQ
A19: 7 | B19: 14005 | C19: ARDY FATURROHMAN
A20: 8 | B20: 14006 | C20: AUSHAF RAFFA ARUNA
A21: 9 | B21: 14007 | C21: BAKRIF HAKIKI
A22: 10 | B22: 14008 | C22: DAFFA HILMI RAMADHAN
A23: 11 | B23: 14009 | C23: DEAZ MARFELINO
A24: 12 | B24: 14011 | C24: DHONAN ZHALIFUNNAS
... A46: 34 | B46: 14035 | C46: ZIKRA ALFIAN NUR FITRON
A47: 35
A48: 36
A49: 37
A51: CATATAN HARIAN GURU | L51: Deskripsi Penilaian
A52: NO | B52: Tanggal | C52: Kegiatan Pembelajaran | D52: Materi Pembelajaran
A53: 1 | C53: Menerangkan/Diskusi/Tugas/Ujian*) | L53: 1
A54: 2 | C54: Menerangkan/Diskusi/Tugas/Ujian*) | L54: 2
A55: 3 | C55: Menerangkan/Diskusi/Tugas/Ujian*) | L55: 3
A56: 4 | C56: Menerangkan/Diskusi/Tugas/Ujian*) | L56: 4
A57: 5 | C57: Menerangkan/Diskusi/Tugas/Ujian*) | L57: 5
A58: Keterangan : | K58: Bantul,……………………………………….
A59: Penilaian diisikan setiap kali melakukan penilaian harian berupa tugas, tes tertulis, tes lisan, tes unjuk kerja atau portopolio ( Validasi setiap Bulan ) | K59: Guru Bidang Studi
A61: *) Pada kolom kegiatan pembelajaran coret yang tidak dilakukan, kegiatan pembelajaran bisa lebih dari satu kegiatan
K62: …………………………………………….
K63: NBM…………………………………….
A65: *) 14-okt-2025

Sheet TKRO 3
M1: KUR/PPB/FO-002
M2: Rev. 02 / 15 Juli 2019
A3: DAFTAR HADIR SISWA
A4: ( CATATAN HARIAN GURU DAN DAFTAR NILAI )
A5: SMK MUHAMMADIYAH 1 BANTUL
A6: KELAS : XI TKR 3
A8: MATA PELAJARAN :.................................................. | L8: SEMESTER :..................
A9: GURU MATA PELAJARAN :.................................................. | L9: TAHUN PELAJARAN : 2025/2026
A10: WALI AMANAH | C10: : Kristina Murtiningsih, S.Pd
A11: NOMOR | C11: NAMA | D11: BULAN : | I11: JUMLAH | L11: Nilai Tugas Harian | Q11: Nilai KD
A12: URUT | B12: INDUK | I12: S | J12: I | K12: A | L12: 1 | M12: 2 | N12: 3 | O12: 4 | P12: 5
A13: 1 | B13: 14036 | C13: ACHSAN YOGA DUANA
A14: 2 | B14: 14037 | C14: ADNAN ARYA SAPUTRA
A15: 3 | B15: 14038 | C15: AKBAR ABDUL HAMID
A16: 4 | B16: 14039 | C16: ANDREW RADITYA SUPARJAN
A17: 5 | B17: 14040 | C17: ARDE INDRA WIJAYA
A18: 6 | B18: 14041 | C18: ARIF RAHMADI
A19: 7 | B19: 14042 | C19: AZIZ RIZKI ARTA SAPUTRA
A20: 8 | B20: 14043 | C20: BAYU REZKY PRATAMA
A21: 9 | B21: 14044 | C21: DAFFA WAHIDUN RAFIF
A22: 10 | B22: 14045 | C22: DEOVANI NUR WIJAYA
A23: 11 | B23: 14046 | C23: DIAZ SYAHMUDA ADI PURNAMA
A24: 12 | B24: 14048 | C24: FAISHAL NABHAN MUWAFFAQ
... A44: 32 | B44: 14068 | C44: ZUFAN LUTFI DWI HANAFI
A45: 33
A46: 34
A47: 35
A48: 36
A50: CATATAN HARIAN GURU | L50: Deskripsi Penilaian
A51: NO | B51: Tanggal | C51: Kegiatan Pembelajaran | D51: Materi Pembelajaran
A52: 1 | C52: Menerangkan/Diskusi/Tugas/Ujian*) | L52: 1
A53: 2 | C53: Menerangkan/Diskusi/Tugas/Ujian*) | L53: 2
A54: 3 | C54: Menerangkan/Diskusi/Tugas/Ujian*) | L54: 3
A55: 4 | C55: Menerangkan/Diskusi/Tugas/Ujian*) | L55: 4
A56: 5 | C56: Menerangkan/Diskusi/Tugas/Ujian*) | L56: 5
A57: Keterangan : | K57: Bantul,……………………………………….
A58: Penilaian diisikan setiap kali melakukan penilaian harian berupa tugas, tes tertulis, tes lisan, tes unjuk kerja atau portopolio ( Validasi setiap Bulan ) | K58: Guru Bidang Studi
A60: *) Pada kolom kegiatan pembelajaran coret yang tidak dilakukan, kegiatan pembelajaran bisa lebih dari satu kegiatan
K61: …………………………………………….
K62: NBM…………………………………….
...

Sheet TKRO 4
M1: KUR/PPB/FO-002
M2: Rev. 02 / 15 Juli 2019
A3: DAFTAR HADIR SISWA
A4: ( CATATAN HARIAN GURU DAN DAFTAR NILAI )
A5: SMK MUHAMMADIYAH 1 BANTUL
A6: KELAS : XI TKR 4
A8: MATA PELAJARAN :.................................................. | L8: SEMESTER :..................
A9: GURU MATA PELAJARAN :.................................................. | L9: TAHUN PELAJARAN : 2025/2026
A10: WALI AMANAH | C10: : Sigit Purnawan, S.Pd
A11: NOMOR | C11: NAMA | D11: BULAN : | I11: JUMLAH | L11: Nilai Tugas Harian | Q11: Nilai KD
A12: URUT | B12: INDUK | I12: S | J12: I | K12: A | L12: 1 | M12: 2 | N12: 3 | O12: 4 | P12: 5
A13: 1 | B13: 14070 | C13: ADJI NURSETO
A14: 2 | B14: 14071 | C14: ALDIN ESTU PRAYOGI
A15: 3 | B15: 14072 | C15: ANDHIKA ADIYATMA JAYA
A16: 4 | B16: 14073 | C16: ANGGER DAMARJATI
A17: 5 | B17: 14074 | C17: ARDHAN BINTANG PAMUNGKAS
A18: 6 | B18: 14075 | C18: ARJUN ARYA SAPUTRA
A19: 7 | B19: 14076 | C19: BAGAS ADHI PRASETYA
A20: 8 | B20: 14077 | C20: BIMA SURYA TIMUR
A21: 9 | B21: 14078 | C21: DAVA AJITYA PUTRA
A22: 10 | B22: 14079 | C22: DESTYOVAN NUR 'AIZAM
A23: 11 | B23: 14080 | C23: DIKA AGUS SETYAWAN
A24: 12 | B24: 14081 | C24: FADHLAN AQILA ZAKI
... A45: 33 | B45: 14104 | C45: YOGA MAULANA AFIQ
A46: 34
A47: 35
A48: 36
A50: CATATAN HARIAN GURU | L50: Deskripsi Penilaian
A51: NO | B51: Tanggal | C51: Kegiatan Pembelajaran | D51: Materi Pembelajaran
A52: 1 | C52: Menerangkan/Diskusi/Tugas/Ujian*) | L52: 1
A53: 2 | C53: Menerangkan/Diskusi/Tugas/Ujian*) | L53: 2
A54: 3 | C54: Menerangkan/Diskusi/Tugas/Ujian*) | L54: 3
A55: 4 | C55: Menerangkan/Diskusi/Tugas/Ujian*) | L55: 4
A56: 5 | C56: Menerangkan/Diskusi/Tugas/Ujian*) | L56: 5
A57: Keterangan : | K57: Bantul,……………………………………….
A58: Penilaian diisikan setiap kali melakukan penilaian harian berupa tugas, tes tertulis, tes lisan, tes unjuk kerja atau portopolio ( Validasi setiap Bulan ) | K58: Guru Bidang Studi
A60: *) Pada kolom kegiatan pembelajaran coret yang tidak dilakukan, kegiatan pembelajaran bisa lebih dari satu kegiatan
K61: …………………………………………….
K62: NBM…………………………………….
A64: *) 14-okt-2025

Sheet TKRO 5
M1: KUR/PPB/FO-002
M2: Rev. 02 / 15 Juli 2019
A3: DAFTAR HADIR SISWA
A4: ( CATATAN HARIAN GURU DAN DAFTAR NILAI )
A5: SMK MUHAMMADIYAH 1 BANTUL
A6: KELAS : XI TKR 5
A8: MATA PELAJARAN :.................................................. | L8: SEMESTER :..................
A9: GURU MATA PELAJARAN :.................................................. | L9: TAHUN PELAJARAN : 2025/2026
A10: WALI AMANAH | C10: : Abdullah Dian Febriyanta, S.Pd
A11: NOMOR | C11: NAMA | D11: BULAN : | I11: JUMLAH | L11: Nilai Tugas Harian | Q11: Nilai KD
A12: URUT | B12: INDUK | I12: S | J12: I | K12: A | L12: 1 | M12: 2 | N12: 3 | O12: 4 | P12: 5
A13: 1 | B13: 14105 | C13: ADIB ROSYADI
A14: 2 | B14: 14106 | C14: AHMAD ADI SUSENO
A15: 3 | B15: 14107 | C15: ALIEF ALFIAN FAJAR CAHYO
A16: 4 | B16: 14108 | C16: ANDIKA PRASETYA
A17: 5 | B17: 14109 | C17: ANGGER PUTRA PRATAMA
A18: 6 | B18: 14110 | C18: ARDHIKA REZA SAPUTRA
A19: 7 | B19: 14111 | C19: ATHAYA NAQA RIFAI
A20: 8 | B20: 14112 | C20: BAGAS IHSANUDIN
A21: 9 | B21: 14114 | C21: DENIS SHATA NUR WANDARU
A22: 10 | B22: 14115 | C22: DIMAS HARY SYAHPUTRA
A23: 11 | B23: 14116 | C23: FADLY KURNIAWAN
A24: 12 | B24: 14117 | C24: FAJAR AGUS PONINGAL
... A41: 29 | B41: 14136 | C41: VAVIAN DAVA YUGANTHA
A42: 30
A43: 31
A44: 32
A45: 33
A46: 34
A47: 35
A48: 36
A50: CATATAN HARIAN GURU | L50: Deskripsi Penilaian
A51: NO | B51: Tanggal | C51: Kegiatan Pembelajaran | D51: Materi Pembelajaran
A52: 1 | C52: Menerangkan/Diskusi/Tugas/Ujian*) | L52: 1
A53: 2 | C53: Menerangkan/Diskusi/Tugas/Ujian*) | L53: 2
A54: 3 | C54: Menerangkan/Diskusi/Tugas/Ujian*) | L54: 3
A55: 4 | C55: Menerangkan/Diskusi/Tugas/Ujian*) | L55: 4
A56: 5 | C56: Menerangkan/Diskusi/Tugas/Ujian*) | L56: 5
A57: Keterangan : | K57: Bantul,……………………………………….
A58: Penilaian diisikan setiap kali melakukan penilaian harian berupa tugas, tes tertulis, tes lisan, tes unjuk kerja atau portopolio ( Validasi setiap Bulan ) | K58: Guru Bidang Studi
...

Sheet TBSM 1
M1: KUR/PPB/FO-002
M2: Rev. 02 / 15 Juli 2019
A3: DAFTAR HADIR SISWA
A4: ( CATATAN HARIAN GURU DAN DAFTAR NILAI )
A5: SMK MUHAMMADIYAH 1 BANTUL
A6: KELAS : XI TSM 1
A8: MATA PELAJARAN :.................................................. | L8: SEMESTER :..................
A9: GURU MATA PELAJARAN :.................................................. | L9: TAHUN PELAJARAN : 2025/2026
A10: WALI AMANAH | C10: : Endah Soffiati, S.Si
A11: NOMOR | C11: NAMA | D11: BULAN : | I11: JUMLAH | L11: Nilai Tugas Harian | Q11: Nilai KD
A12: URUT | B12: INDUK | I12: S | J12: I | K12: A | L12: 1 | M12: 2 | N12: 3 | O12: 4 | P12: 5
A13: 1 | B13: 14138 | C13: ABDUL AZIZ MUNIF
A14: 2 | B14: 14141 | C14: ALFIAN DECO SAPUTRA
A15: 3 | B15: 14142 | C15: ALVIANDY HASFI NUGROHO
A16: 4 | B16: 14143 | C16: ANANDA DAVA PUTRA PRATAMA
A17: 5 | B17: 14144 | C17: ANDIKA FELLIX NAVINSAN
A18: 6 | B18: 14145 | C18: ARIEF RASYID SETIAJI
A19: 7 | B19: 14146 | C19: AZZAM ZULFIKAR SETIAWAN
A20: 8 | B20: 14147 | C20: DAVID RADITYA HERMANTO
A21: 9 | B21: 14148 | C21: DERI TRI YANTO
A22: 10 | B22: 14149 | C22: DIMAS SETO PANGESTU
A23: 11 | B23: 14150 | C23: FAIS DWI KURNIAWAN
A24: 12 | B24: 14151 | C24: FAREL PUTRA RAMADHAN
... A45: 33 | B45: 14174 | C45: ZANDRA IKHSAN WAHYU PRATAMA
A46: 34
A47: 35
A48: 36
A49: 37
A51: CATATAN HARIAN GURU | L51: Deskripsi Penilaian
A52: NO | B52: Tanggal | C52: Kegiatan Pembelajaran | D52: Materi Pembelajaran
A53: 1 | C53: Menerangkan/Diskusi/Tugas/Ujian*) | L53: 1
A54: 2 | C54: Menerangkan/Diskusi/Tugas/Ujian*) | L54: 2
A55: 3 | C55: Menerangkan/Diskusi/Tugas/Ujian*) | L55: 3
A56: 4 | C56: Menerangkan/Diskusi/Tugas/Ujian*) | L56: 4
A57: 5 | C57: Menerangkan/Diskusi/Tugas/Ujian*) | L57: 5
A58: Keterangan : | K58: Bantul,……………………………………….
A59: Penilaian diisikan setiap kali melakukan penilaian harian berupa tugas, tes tertulis, tes lisan, tes unjuk kerja atau portopolio ( Validasi setiap Bulan ) | K59: Guru Bidang Studi
A61: *) Pada kolom kegiatan pembelajaran coret yang tidak dilakukan, kegiatan pembelajaran bisa lebih dari satu kegiatan
K62: …………………………………………….
K63: NBM…………………………………….
...

Sheet TBSM 2
M1: KUR/PPB/FO-002
M2: Rev. 02 / 15 Juli 2019
A3: DAFTAR HADIR SISWA
A4: ( CATATAN HARIAN GURU DAN DAFTAR NILAI )
A5: SMK MUHAMMADIYAH 1 BANTUL
A6: KELAS : XI TSM 2
A8: MATA PELAJARAN :.................................................. | L8: SEMESTER :..................
A9: GURU MATA PELAJARAN :.................................................. | L9: TAHUN PELAJARAN : 2025/2026
A10: WALI AMANAH | C10: : Rahmad Novi Wibawa, S.Pd
A11: NOMOR | C11: NAMA | D11: BULAN : | I11: JUMLAH | L11: Nilai Tugas Harian | Q11: Nilai KD
A12: URUT | B12: INDUK | I12: S | J12: I | K12: A | L12: 1 | M12: 2 | N12: 3 | O12: 4 | P12: 5
A13: 1 | B13: 14175 | C13: ABID YULIAN
A14: 2 | B14: 14176 | C14: AJI GALANG ROMADHON
A15: 3 | B15: 14177 | C15: ALENDRA RESTU WIJANARKO
A16: 4 | B16: 14178 | C16: ALVIAN KURNIAWAN
A17: 5 | B17: 14179 | C17: ALVIN AGUNG SAPUTRA
A18: 6 | B18: 14181 | C18: ARJUNA SATRIA TAMA
A19: 7 | B19: 14182 | C19: BAYU AJI PAMUNGKAS
A20: 8 | B20: 14183 | C20: DEANDRA GHANI ALFARIZHI
A21: 9 | B21: 14184 | C21: DEVDAN AFRIZA MIFDLAL
A22: 10 | B22: 14187 | C22: FAJAR PUTRA PRATAMA
A23: 11 | B23: 14188 | C23: FAREL RAFIF SUSILO
A24: 12 | B24: 14189 | C24: FERDIAN DWI NURRAHMAT
... A45: 33 | B45: 14212 | C45: ZANUAR WAHYU PRATAMA
A46: 34
A47: 35
A48: 36
A49: 37
A50: 38
A52: CATATAN HARIAN GURU | L52: Deskripsi Penilaian
A53: NO | B53: Tanggal | C53: Kegiatan Pembelajaran | D53: Materi Pembelajaran
A54: 1 | C54: Menerangkan/Diskusi/Tugas/Ujian*) | L54: 1
A55: 2 | C55: Menerangkan/Diskusi/Tugas/Ujian*) | L55: 2
A56: 3 | C56: Menerangkan/Diskusi/Tugas/Ujian*) | L56: 3
A57: 4 | C57: Menerangkan/Diskusi/Tugas/Ujian*) | L57: 4
A58: 5 | C58: Menerangkan/Diskusi/Tugas/Ujian*) | L58: 5
A59: Keterangan : | K59: Bantul,……………………………………….
A60: Penilaian diisikan setiap kali melakukan penilaian harian berupa tugas, tes tertulis, tes lisan, tes unjuk kerja atau portopolio ( Validasi setiap Bulan ) | K60: Guru Bidang Studi
A62: *) Pada kolom kegiatan pembelajaran coret yang tidak dilakukan, kegiatan pembelajaran bisa lebih dari satu kegiatan
K63: …………………………………………….
...

Sheet TBSM 3
M1: KUR/PPB/FO-002
M2: Rev. 02 / 15 Juli 2019
A3: DAFTAR HADIR SISWA
A4: ( CATATAN HARIAN GURU DAN DAFTAR NILAI )
A5: SMK MUHAMMADIYAH 1 BANTUL
A6: KELAS : XI TSM 3
A8: MATA PELAJARAN :.................................................. | L8: SEMESTER :..................
A9: GURU MATA PELAJARAN :.................................................. | L9: TAHUN PELAJARAN : 2025/2026
A10: WALI AMANAH | C10: : Rosita Dwi Noegrahaeni, S.Pd
A11: NOMOR | C11: NAMA | D11: BULAN : | I11: JUMLAH | L11: Nilai Tugas Harian | Q11: Nilai KD
A12: URUT | B12: INDUK | I12: S | J12: I | K12: A | L12: 1 | M12: 2 | N12: 3 | O12: 4 | P12: 5
A13: 1 | B13: 14213 | C13: ABIMANYU PRIAMBUDI
A14: 2 | B14: 14214 | C14: AJI PUTRA WIJAYA
A15: 3 | B15: 14215 | C15: ALFAREZY RIDHO TIYANTORO
A16: 4 | B16: 14216 | C16: ALI MURTADHO
A17: 5 | B17: 14217 | C17: ANDHIKA MAULANA PUTRA
A18: 6 | B18: 14219 | C18: ARYAMA WAHYU NUGROHO
A19: 7 | B19: 14220 | C19: DANUJA NADJID MAMDUH
A20: 8 | B20: 14222 | C20: DHIKA PRATAMA PUTRA
A21: 9 | B21: 14223 | C21: ERIQ NUR ROMELAN
A22: 10 | B22: 14224 | C22: FAHRY SYAHRUL RAMADHAN
A23: 11 | B23: 14225 | C23: FALIH ANOVEARIO SANTOSO
A24: 12 | B24: 14261 | C24: FAREL BANGUN HUTAMA
... A46: 34 | B46: 14248 | C46: ZASIR MAULANA IBRAHIM
A47: 35
A48: 36
A49: 37
A51: CATATAN HARIAN GURU | L51: Deskripsi Penilaian
A52: NO | B52: Tanggal | C52: Kegiatan Pembelajaran | D52: Materi Pembelajaran
A53: 1 | C53: Menerangkan/Diskusi/Tugas/Ujian*) | L53: 1
A54: 2 | C54: Menerangkan/Diskusi/Tugas/Ujian*) | L54: 2
A55: 3 | C55: Menerangkan/Diskusi/Tugas/Ujian*) | L55: 3
A56: 4 | C56: Menerangkan/Diskusi/Tugas/Ujian*) | L56: 4
A57: 5 | C57: Menerangkan/Diskusi/Tugas/Ujian*) | L57: 5
A58: Keterangan : | K58: Bantul,……………………………………….
A59: Penilaian diisikan setiap kali melakukan penilaian harian berupa tugas, tes tertulis, tes lisan, tes unjuk kerja atau portopolio ( Validasi setiap Bulan ) | K59: Guru Bidang Studi
A61: *) Pada kolom kegiatan pembelajaran coret yang tidak dilakukan, kegiatan pembelajaran bisa lebih dari satu kegiatan
K62: …………………………………………….
K63: NBM…………………………………….
A65: *) 16-jun-2025

Sheet TBSM 4
M1: KUR/PPB/FO-002
M2: Rev. 02 / 15 Juli 2019
A3: DAFTAR HADIR SISWA
A4: ( CATATAN HARIAN GURU DAN DAFTAR NILAI )
A5: SMK MUHAMMADIYAH 1 BANTUL
A6: KELAS : XI TSM 4
A8: MATA PELAJARAN :.................................................. | L8: SEMESTER :..................
A9: GURU MATA PELAJARAN :.................................................. | L9: TAHUN PELAJARAN : 2025/2026
A10: WALI AMANAH | C10: : Tubagus Mutasindra, S.Pd
A11: NOMOR | C11: NAMA | D11: BULAN : | I11: JUMLAH | L11: Nilai Tugas Harian | Q11: Nilai KD
A12: URUT | B12: INDUK | I12: S | J12: I | K12: A | L12: 1 | M12: 2 | N12: 3 | O12: 4 | P12: 5
A13: 1 | B13: 14249 | C13: ADAM WISNU AL FIRMAN
A14: 2 | B14: 14252 | C14: ALIF REIHANSYAH SAPUTRA
A15: 3 | B15: 14254 | C15: ARDHIFA KHOIRUL AZZA
A16: 4 | B16: 14255 | C16: AULIYAU RAHMAN MAULIDI
A17: 5 | B17: 14256 | C17: DAVA' ALFARIZZI
A18: 6 | B18: 14258 | C18: DIMAS DWI SATRIA
A19: 7 | B19: 14259 | C19: FABIAN KEVIN RAMADHAN
A20: 8 | B20: 14260 | C20: FAIRUZIZUAN IBRAHIMOVIC
A21: 9 | B21: 14265 | C21: KURNIAWAN BUMI
A22: 10 | B22: 14266 | C22: MAULANA AGUNG SEBAYU
A23: 11 | B23: 14267 | C23: MUHAMMAD ARSHAQ EL-HAQQANI
A24: 12 | B24: 14269 | C24: MUHAMMAD NUR IRSYAD
... A36: 24 | B36: 14285 | C36: ZIDAN CHANDRA WIBAWA
A37: 25
A38: 26
A39: 27
A40: 28
A41: 29
A42: 30
A43: 31
A44: 32
A45: 33
A46: 34
A47: 35
A48: 36
A50: CATATAN HARIAN GURU | L50: Deskripsi Penilaian
A51: NO | B51: Tanggal | C51: Kegiatan Pembelajaran | D51: Materi Pembelajaran
A52: 1 | C52: Menerangkan/Diskusi/Tugas/Ujian*) | L52: 1
A53: 2 | C53: Menerangkan/Diskusi/Tugas/Ujian*) | L53: 2
...

Sheet RPL 1
M1: KUR/PPB/FO-002
M2: Rev. 02 / 15 Juli 2019
A3: DAFTAR HADIR SISWA
A4: ( CATATAN HARIAN GURU DAN DAFTAR NILAI )
A5: SMK MUHAMMADIYAH 1 BANTUL
A6: KELAS : XI RPL 1
A8: MATA PELAJARAN :.................................................. | L8: SEMESTER :..................
A9: GURU MATA PELAJARAN :.................................................. | L9: TAHUN PELAJARAN : 2025/2026
A10: WALI AMANAH | C10: : Rr. Swisti Pritandari, S.Kom
A11: NOMOR | C11: NAMA | D11: BULAN : | I11: JUMLAH | L11: Nilai Tugas Harian | Q11: Nilai KD
A12: URUT | B12: INDUK | I12: S | J12: I | K12: A | L12: 1 | M12: 2 | N12: 3 | O12: 4 | P12: 5
A13: 1 | B13: 14286 | C13: ADE SUKMA RISTY ALDI
A14: 2 | B14: 14287 | C14: AINUGRAH AFFIF FEBRYANO
A15: 3 | B15: 14288 | C15: ALAYKA SAFA
A16: 4 | B16: 14289 | C16: ALERASYA BINTANG ADITYA
A17: 5 | B17: 14290 | C17: ALIF AZIZAN AMIRUDIN
A18: 6 | B18: 14291 | C18: ASHELIA REYVA SAFANA
A19: 7 | B19: 14292 | C19: AXEL SURYA PUTRA PRATAMA
A20: 8 | B20: 14293 | C20: CITRA ATHAYA SHYFA
A21: 9 | B21: 14294 | C21: DINDA SINTIASARI
A22: 10 | B22: 14295 | C22: FACHRIANSYAH AL MA'RUF
A23: 11 | B23: 14296 | C23: FAISHAL HAFIZH RAMADHAN
A24: 12 | B24: 14297 | C24: FARA AMILIA PUTRI
... A39: 27 | B39: 14313 | C39: ZAHRA NESHIA VIVIYANTI
A40: 28
A41: 29
A42: 30
A44: CATATAN HARIAN GURU | L44: Deskripsi Penilaian
A45: NO | B45: Tanggal | C45: Kegiatan Pembelajaran | D45: Materi Pembelajaran
A46: 1 | C46: Menerangkan/Diskusi/Tugas/Ujian*) | L46: 1
A47: 2 | C47: Menerangkan/Diskusi/Tugas/Ujian*) | L47: 2
A48: 3 | C48: Menerangkan/Diskusi/Tugas/Ujian*) | L48: 3
A49: 4 | C49: Menerangkan/Diskusi/Tugas/Ujian*) | L49: 4
A50: 5 | C50: Menerangkan/Diskusi/Tugas/Ujian*) | L50: 5
A51: Keterangan : | K51: Bantul,……………………………………….
A52: Penilaian diisikan setiap kali melakukan penilaian harian berupa tugas, tes tertulis, tes lisan, tes unjuk kerja atau portopolio ( Validasi setiap Bulan ) | K52: Guru Bidang Studi
A54: *) Pada kolom kegiatan pembelajaran coret yang tidak dilakukan, kegiatan pembelajaran bisa lebih dari satu kegiatan
K55: …………………………………………….
K56: NBM…………………………………….
A58: *) 3-nov-2025

Sheet RPL 2
M1: KUR/PPB/FO-002
M2: Rev. 02 / 15 Juli 2019
A3: DAFTAR HADIR SISWA
A4: ( CATATAN HARIAN GURU DAN DAFTAR NILAI )
A5: SMK MUHAMMADIYAH 1 BANTUL
A6: KELAS : XI RPL 2
A8: MATA PELAJARAN :.................................................. | L8: SEMESTER :..................
A9: GURU MATA PELAJARAN :.................................................. | L9: TAHUN PELAJARAN : 2025/2026
A10: WALI AMANAH | C10: : Dian Tri Utami, S.Pd
A11: NOMOR | C11: NAMA | D11: BULAN : | I11: JUMLAH | L11: Nilai Tugas Harian | Q11: Nilai KD
A12: URUT | B12: INDUK | I12: S | J12: I | K12: A | L12: 1 | M12: 2 | N12: 3 | O12: 4 | P12: 5
A13: 1 | B13: 14314 | C13: ADITYA DWI CAHYANTO
A14: 2 | B14: 14315 | C14: AKHMAD FAIZUN
A15: 3 | B15: 14316 | C15: ALFIAN MUSTOFA
A16: 4 | B16: 14317 | C16: ALVARO NIBRAS PRATISTA
A17: 5 | B17: 14318 | C17: ASNI MUHAMMAD RIZAL
A18: 6 | B18: 14319 | C18: BAYU RIZKY ADITYA
A19: 7 | B19: 14320 | C19: DAVA BAGAS RIZKYATAMA
A20: 8 | B20: 14321 | C20: DESTRIAN ADIFA WISANTO
A21: 9 | B21: 14322 | C21: FACHUR RAHMAN
A22: 10 | B22: 14323 | C22: FAISHAL NUR RIZKY RAMADHAN
A23: 11 | B23: 14324 | C23: FATUR ROHIM
A24: 12 | B24: 14325 | C24: FATUR ROHMAN
... A40: 28 | B40: 14340 | C40: WISANGGENI TIRTO DJATI
A41: 29
A42: 30
A44: CATATAN HARIAN GURU | L44: Deskripsi Penilaian
A45: NO | B45: Tanggal | C45: Kegiatan Pembelajaran | D45: Materi Pembelajaran
A46: 1 | C46: Menerangkan/Diskusi/Tugas/Ujian*) | L46: 1
A47: 2 | C47: Menerangkan/Diskusi/Tugas/Ujian*) | L47: 2
A48: 3 | C48: Menerangkan/Diskusi/Tugas/Ujian*) | L48: 3
A49: 4 | C49: Menerangkan/Diskusi/Tugas/Ujian*) | L49: 4
A50: 5 | C50: Menerangkan/Diskusi/Tugas/Ujian*) | L50: 5
A51: Keterangan : | K51: Bantul,……………………………………….
A52: Penilaian diisikan setiap kali melakukan penilaian harian berupa tugas, tes tertulis, tes lisan, tes unjuk kerja atau portopolio ( Validasi setiap Bulan ) | K52: Guru Bidang Studi
A54: *) Pada kolom kegiatan pembelajaran coret yang tidak dilakukan, kegiatan pembelajaran bisa lebih dari satu kegiatan
K55: …………………………………………….
K56: NBM…………………………………….
A58: *) 12-agu-2024

Sheet RPL 3
M1: KUR/PPB/FO-002
M2: Rev. 02 / 15 Juli 2019
A3: DAFTAR HADIR SISWA
A4: ( CATATAN HARIAN GURU DAN DAFTAR NILAI )
A5: SMK MUHAMMADIYAH 1 BANTUL
A6: KELAS : XI RPL 3
A8: MATA PELAJARAN :.................................................. | L8: SEMESTER :..................
A9: GURU MATA PELAJARAN :.................................................. | L9: TAHUN PELAJARAN : 2025/2026
A10: WALI AMANAH | C10: : Usfatun Kasanah, S.Kom
A11: NOMOR | C11: NAMA | D11: BULAN : | I11: JUMLAH | L11: Nilai Tugas Harian | Q11: Nilai KD
A12: URUT | B12: INDUK | I12: S | J12: I | K12: A | L12: 1 | M12: 2 | N12: 3 | O12: 4 | P12: 5
A13: 1 | B13: 14341 | C13: AHMAD IKHSAN HARTONO
A14: 2 | B14: 14342 | C14: ALFIQO RIMIDHA FALIKH MURIANA
A15: 3 | B15: 14371 | C15: ANANG NUR WIJAYANTO
A16: 4 | B16: 14343 | C16: ANDIKA DWI KURNIAWAN
A17: 5 | B17: 14344 | C17: ANGGA WAHYU SAPUTRA
A18: 6 | B18: 14345 | C18: ARBYAN ALIF SAPUTRA
A19: 7 | B19: 14346 | C19: ARKAN DHIYA RAISAN PRADANA
A20: 8 | B20: 14347 | C20: ASROFI RAMADANI
A21: 9 | B21: 14348 | C21: DAFTA HAFIZ AFFANUDIN
A22: 10 | B22: 14349 | C22: DESTRA BINTANG WIJAYA
A23: 11 | B23: 14350 | C23: ELANG SANJAYA
A24: 12 | B24: 14351 | C24: FAIQ KHOLILU ROHMAN
... A40: 28 | B40: 14366 | C40: USAMAH FAQIH AHMAD
A41: 29
A42: 30
A44: CATATAN HARIAN GURU | L44: Deskripsi Penilaian
A45: NO | B45: Tanggal | C45: Kegiatan Pembelajaran | D45: Materi Pembelajaran
A46: 1 | C46: Menerangkan/Diskusi/Tugas/Ujian*) | L46: 1
A47: 2 | C47: Menerangkan/Diskusi/Tugas/Ujian*) | L47: 2
A48: 3 | C48: Menerangkan/Diskusi/Tugas/Ujian*) | L48: 3
A49: 4 | C49: Menerangkan/Diskusi/Tugas/Ujian*) | L49: 4
A50: 5 | C50: Menerangkan/Diskusi/Tugas/Ujian*) | L50: 5
A51: Keterangan : | K51: Bantul,……………………………………….
A52: Penilaian diisikan setiap kali melakukan penilaian harian berupa tugas, tes tertulis, tes lisan, tes unjuk kerja atau portopolio ( Validasi setiap Bulan ) | K52: Guru Bidang Studi
A54: *) Pada kolom kegiatan pembelajaran coret yang tidak dilakukan, kegiatan pembelajaran bisa lebih dari satu kegiatan
K55: …………………………………………….
K56: NBM…………………………………….
A58: *) 15-agu-2024

Sheet stat
A1: NO | B1: KELAS | C1: JUMLAH
A2: 1 | B2: XI TAV / TE | C2: =COUNTA('TAV 1'!$C$13:$C$46) -> 30
A3: 2 | B3: XI TPM 1 / TM 1 | C3: =COUNTA('TPM 1'!$C$13:$C$46) -> 34 | E3: NIS TERAKHIR : | H3: 14374 | I3: RADEN MOH ZULKARNAEN AL FARISSI | J3: 10 TM 1
A4: 3 | B4: XI TPM 2 / TM 2 | C4: =COUNTA('TPM 2'!$C$13:$C$48) -> 30
A5: 4 | B5: XI TKRO 1 / TO 1 | C5: =COUNTA('TKRO 1'!$C$13:$C$48) -> 28
A6: 5 | B6: XI TKRO 2 / TO 2 | C6: =COUNTA('TKRO 2'!$C$13:$C$46) -> 34
A7: 6 | B7: XI TKRO 3 / TO 3 | C7: =COUNTA('TKRO 3'!$C$13:$C$49) -> 32
A8: 7 | B8: XI TKRO 4 / TO 4 | C8: =COUNTA('TKRO 4'!$C$13:$C$49) -> 33
A9: 8 | B9: XI TKRO 5 / TO 5 | C9: =COUNTA('TKRO 5'!$C$13:$C$49) -> 29
A10: 9 | B10: XI TBSM 1 / TO 6 | C10: =COUNTA('TBSM 1'!$C$13:$C$50) -> 33
A11: 10 | B11: XI TBSM 2 / TO 7 | C11: =COUNTA('TBSM 2'!$C$13:$C$51) -> 33
A12: 11 | B12: XI TBSM 3 / TO 8 | C12: =COUNTA('TBSM 3'!$C$13:$C$50) -> 34
A13: 12 | B13: XI TBSM 4 / TO 9 | C13: =COUNTA('TBSM 4'!$C$13:$C$49) -> 24
A14: 13 | B14: XI RPL 1 / PPLG 1 | C14: =COUNTA('RPL 1'!$C$13:$C$39) -> 27
A15: 14 | B15: XI RPL 2 / PPLG 2 | C15: =COUNTA('RPL 2'!$C$13:$C$42) -> 28
A16: 15 | B16: XI RPL 3 / PPLG 3 | C16: =COUNTA('RPL 3'!$C$13:$C$42) -> 28
B17: TOTAL | C17: =SUM(C2:C16) -> 457

Sheet Total
A1: NO | B1: NIS | C1: NAMA SISWA | D1: KELAS | E1: KELAS 2 | F1: KET | I1: JURUSAN | J1: JUMLAH AWAL | K1: ROMBEL | L1: AKTIF | M1: KELUAR | N1: TOTAL AKTIF | O1: TOTAL KELUAR
A2: 1 | B2: 13862 | C2: AFIFAN PUTRA MUKLISHAN | D2: 11 TAV | E2: 11 TE | F2: AKTIF | I2: TE / TAV | J2: 31 | K2: 1 | L2: =COUNTIFS($E$2:$E$518,"11 TE",$F$2:$F$518,"AKTIF") -> 30 | M2: =COUNTIFS($E$2:$E$518,"11 TE",$F$2:$F$518,"KELUAR") -> 1 | N2: =SUM(L2) -> 30 | O2: =SUM(M2) -> 1
A3: 2 | B3: 13863 | C3: AGUS GALIH BUDI PRAKOSO | D3: 11 TAV | E3: 11 TE | F3: KELUAR | I3: TM / TPM | J3: 74 | K3: 1 | L3: =COUNTIFS($E$2:$E$518,"11 TM 1",$F$2:$F$518,"AKTIF") -> 34 | M3: =COUNTIFS($E$2:$E$518,"11 TM 1",$F$2:$F$518,"KELUAR") -> 4 | N3: =SUM(L3:L4) -> 64 | O3: =SUM(M3:M4) -> 10
A4: 3 | B4: 13864 | C4: AHMAD FALAKHUL MUTTAQI | D4: 11 TAV | E4: 11 TE | F4: AKTIF | K4: 2 | L4: =COUNTIFS($E$2:$E$518,"11 TM 2",$F$2:$F$518,"AKTIF") -> 30 | M4: =COUNTIFS($E$2:$E$518,"11 TM 2",$F$2:$F$518,"KELUAR") -> 6
A5: 4 | B5: 13865 | C5: ALBANI DIAN RASYID | D5: 11 TAV | E5: 11 TE | F5: AKTIF | I5: TO / TKR | J5: 173 | K5: 1 | L5: =COUNTIFS($E$2:$E$518,"11 TO 1",$F$2:$F$518,"AKTIF") -> 28 | M5: =COUNTIFS($E$2:$E$518,"11 TO 1",$F$2:$F$518,"KELUAR") -> 7 | N5: =SUM(L5:L9) -> 156 | O5: =SUM(M5:M9) -> 17
A6: 5 | B6: 13866 | C6: ALDIANO RIZKY | D6: 11 TAV | E6: 11 TE | F6: AKTIF | K6: 2 | L6: =COUNTIFS($E$2:$E$518,"11 TO 2",$F$2:$F$518,"AKTIF") -> 34 | M6: =COUNTIFS($E$2:$E$518,"11 TO 2",$F$2:$F$518,"KELUAR") -> 3
A7: 6 | B7: 13867 | C7: ALFIN MAULANA PUTRA | D7: 11 TAV | E7: 11 TE | F7: AKTIF | K7: 3 | L7: =COUNTIFS($E$2:$E$518,"11 TO 3",$F$2:$F$518,"AKTIF") -> 32 | M7: =COUNTIFS($E$2:$E$518,"11 TO 3",$F$2:$F$518,"KELUAR") -> 1
A8: 7 | B8: 13868 | C8: ARKHAB ISLAM SUPRIYADI | D8: 11 TAV | E8: 11 TE | F8: AKTIF | K8: 4 | L8: =COUNTIFS($E$2:$E$518,"11 TO 4",$F$2:$F$518,"AKTIF") -> 33 | M8: =COUNTIFS($E$2:$E$518,"11 TO 4",$F$2:$F$518,"KELUAR") -> 2
A9: 8 | B9: 13869 | C9: BAGAS ALAM NURSETO | D9: 11 TAV | E9: 11 TE | F9: AKTIF | K9: 5 | L9: =COUNTIFS($E$2:$E$518,"11 TO 5",$F$2:$F$518,"AKTIF") -> 29 | M9: =COUNTIFS($E$2:$E$518,"11 TO 5",$F$2:$F$518,"KELUAR") -> 4
A10: 9 | B10: 13870 | C10: DAFFAZACKY NURFIANSYAH | D10: 11 TAV | E10: 11 TE | F10: AKTIF | I10: TO / TSM | J10: 149 | K10: 1 | L10: =COUNTIFS($E$2:$E$518,"11 TO 6",$F$2:$F$518,"AKTIF") -> 33 | M10: =COUNTIFS($E$2:$E$518,"11 TO 6",$F$2:$F$518,"KELUAR") -> 4 | N10: =SUM(L10:L13) -> 124 | O10: =SUM(M10:M13) -> 25
A11: 10 | B11: 13871 | C11: DHIMAS SUNGKONO PUTRO | D11: 11 TAV | E11: 11 TE | F11: AKTIF | K11: 2 | L11: =COUNTIFS($E$2:$E$518,"11 TO 7",$F$2:$F$518,"AKTIF") -> 33 | M11: =COUNTIFS($E$2:$E$518,"11 TO 7",$F$2:$F$518,"KELUAR") -> 5
A12: 11 | B12: 13872 | C12: ELANGGA BAGAS AJI SAPUTRA | D12: 11 TAV | E12: 11 TE | F12: AKTIF | K12: 3 | L12: =COUNTIFS($E$2:$E$518,"11 TO 8",$F$2:$F$518,"AKTIF") -> 34 | M12: =COUNTIFS($E$2:$E$518,"11 TO 8",$F$2:$F$518,"KELUAR") -> 4
A13: 12 | B13: 13873 | C13: FAHRI ABDILLAH | D13: 11 TAV | E13: 11 TE | F13: AKTIF | K13: 4 | L13: =COUNTIFS($E$2:$E$518,"11 TO 9",$F$2:$F$518,"AKTIF") -> 24 | M13: =COUNTIFS($E$2:$E$518,"11 TO 9",$F$2:$F$518,"KELUAR") -> 12
A14: 13 | B14: 13874 | C14: FAIZZA ISNAN AFFANI | D14: 11 TAV | E14: 11 TE | F14: AKTIF | I14: PPLG / RPL | J14: 86 | K14: 1 | L14: =COUNTIFS($E$2:$E$518,"11 PPLG 1",$F$2:$F$518,"AKTIF") -> 27 | M14: =COUNTIFS($E$2:$E$518,"11 PPLG 1",$F$2:$F$518,"KELUAR") -> 3 | N14: =SUM(L14:L16) -> 83 | O14: =SUM(M14:M16) -> 3
A15: 14 | B15: 13875 | C15: FAJAR MUHAMMAD RIZKI | D15: 11 TAV | E15: 11 TE | F15: AKTIF | K15: 2 | L15: =COUNTIFS($E$2:$E$518,"11 PPLG 2",$F$2:$F$518,"AKTIF") -> 28 | M15: =COUNTIFS($E$2:$E$518,"11 PPLG 2",$F$2:$F$518,"KELUAR") -> 0
A16: 15 | B16: 13876 | C16: FATTEGAR YUSUF KHITHOBI | D16: 11 TAV | E16: 11 TE | F16: AKTIF | K16: 3 | L16: =COUNTIFS($E$2:$E$518,"11 PPLG 3",$F$2:$F$518,"AKTIF") -> 28 | M16: =COUNTIFS($E$2:$E$518,"11 PPLG 3",$F$2:$F$518,"KELUAR") -> 0
A17: 16 | B17: 13877 | C17: FRISTAMA DANAR ZAKIYA | D17: 11 TAV | E17: 11 TE | F17: AKTIF | I17: TOTAL | J17: =SUM(J2:J14) -> 513 | K17: =COUNTA(K2:K16) -> 15 | L17: =SUM(L2:L16) -> 457 | M17: =SUM(M2:M16) -> 56 | N17: =SUM(N2:N16) -> 457 | O17: =SUM(O2:O16) -> 56
A18: 17 | B18: 13878 | C18: HAFIF MALIK FALEKHAN | D18: 11 TAV | E18: 11 TE | F18: AKTIF
A19: 18 | B19: 13879 | C19: IRVAN HENDY KURNIAWAN | D19: 11 TAV | E19: 11 TE | F19: AKTIF
A20: 19 | B20: 13880 | C20: MARINTO DIRO SAPUTRO | D20: 11 TAV | E20: 11 TE | F20: AKTIF
A21: 20 | B21: 13881 | C21: MUHAMAD DAFFA ADLY MUSTHOFA | D21: 11 TAV | E21: 11 TE | F21: AKTIF
A22: 21 | B22: 13882 | C22: MUHAMAD SATRIA BUDIADIKARA | D22: 11 TAV | E22: 11 TE | F22: AKTIF
A23: 22 | B23: 13883 | C23: MUHAMMAD ADITYA PRATAMA | D23: 11 TAV | E23: 11 TE | F23: AKTIF
A24: 23 | B24: 13884 | C24: MUHAMMAD FARHAN FIRDAUS | D24: 11 TAV | E24: 11 TE | F24: AKTIF
A25: 24 | B25: 13885 | C25: MUHAMMAD KHOIRUL KHISAN | D25: 11 TAV | E25: 11 TE | F25: AKTIF
A26: 25 | B26: 13886 | C26: MUHAMMAD ZIDAN FATTU ROHMAN | D26: 11 TAV | E26: 11 TE | F26: AKTIF
A27: 26 | B27: 13887 | C27: RIZAL JAHFAL ADZIN | D27: 11 TAV | E27: 11 TE | F27: AKTIF
A28: 27 | B28: 13888 | C28: ROZAN ZAINUL RIJAL | D28: 11 TAV | E28: 11 TE | F28: AKTIF
A29: 28 | B29: 13889 | C29: SEPTIAN ADHIANSYAH RAMADHANI | D29: 11 TAV | E29: 11 TE | F29: AKTIF
... A60: 59 | B60: 13920 | C60: PRADIKA FADLI ALFA RENZA | D60: 11 TPM 1 | E60: 11 TM 1 | F60: KELUAR
A61: 60 | B61: 14374 | C61: RADEN MOH ZULKARNAEN AL FARISSI | D61: 11 TPM 1 | E61: 11 TM 1 | F61: KELUAR | G61: TN
A62: 61 | B62: 13921 | C62: RAMDHANI KARUNIAWAN | D62: 11 TPM 1 | E62: 11 TM 1 | F62: AKTIF
A63: 62 | B63: 13922 | C63: REZA NUR HABIB | D63: 11 TPM 1 | E63: 11 TM 1 | F63: AKTIF
A64: 63 | B64: 13923 | C64: RICHI WAHYU WIBOWO | D64: 11 TPM 1 | E64: 11 TM 1 | F64: AKTIF
A65: 64 | B65: 13924 | C65: RIZAL DIAN RAMADHAN | D65: 11 TPM 1 | E65: 11 TM 1 | F65: AKTIF
A66: 65 | B66: 13925 | C66: RONAA DAFFA PRATAMA | D66: 11 TPM 1 | E66: 11 TM 1 | F66: AKTIF
A67: 66 | B67: 13926 | C67: SYAHRI RAMADHANI | D67: 11 TPM 1 | E67: 11 TM 1 | F67: KELUAR
A68: 67 | B68: 13927 | C68: TIRTA BACHRONI | D68: 11 TPM 1 | E68: 11 TM 1 | F68: AKTIF
A69: 68 | B69: 13928 | C69: YOGA WIJAYA SAPUTRA | D69: 11 TPM 1 | E69: 11 TM 1 | F69: KELUAR
A70: 69 | B70: 13929 | C70: ZAKI KHOIRON | D70: 11 TPM 1 | E70: 11 TM 1 | F70: AKTIF
...

Sheet alamat
A1: NO | B1: NO DAFTAR | C1: NIS | D1: NAMA SISWA | E1: KELAS | F1: KET | G1: HP 1 | H1: HP 2 | I1: DUSUN | J1: RT | K1: DESA | L1: KECAMATAN | M1: ORANG TUA | N1: SMP/MTs | O1: Tgl Lahir
A2: 1 | B2: MSB24-00-069 | C2: 14286 | D2: ADE SUKMA RISTY ALDI | E2: =VLOOKUP(D2,Total!$C$2:$D$518,2,0) -> 11 RPL 1 | F2: =VLOOKUP(C2,Total!$B$2:$F$514,5,0) -> AKTIF | G2: =VLOOKUP($B2,master!$B$3:$S$600,16,0) -> 087839616444 | H2: =VLOOKUP($B2,master!$B$3:$S$600,17,0) -> 0 | I2: =VLOOKUP($B2,master!$B$3:$S$600,8,0) -> SEROPAN III | J2: =VLOOKUP($B2,master!$B$3:$S$600,9,0) -> 8 | K2: =VLOOKUP($B2,master!$B$3:$S$600,11,0) -> MUNTUK | L2: =VLOOKUP($B2,master!$B$3:$S$600,12,0) -> DLINGO | M2: =VLOOKUP($B2,master!$B$3:$S$600,6,0) -> HARNA | N2: =VLOOKUP($B2,master!$B$3:$S$600,15,0) -> SMP MUHAMMADIYAH 2 DLINGO | O2: =VLOOKUP($B2,master!$B$3:$S$600,4,0) -> 6-12-2008
A3: 2 | B3: MSB24-03-402 | C3: 14287 | D3: AINUGRAH AFFIF FEBRYANO | E3: =VLOOKUP(D3,Total!$C$2:$D$518,2,0) -> 11 RPL 1 | F3: =VLOOKUP(C3,Total!$B$2:$F$514,5,0) -> AKTIF | G3: =VLOOKUP($B3,master!$B$3:$S$600,16,0) -> 082135340660 | H3: =VLOOKUP($B3,master!$B$3:$S$600,17,0) -> 085229529454 | I3: =VLOOKUP($B3,master!$B$3:$S$600,8,0) -> DAGEN, GUMUK | J3: =VLOOKUP($B3,master!$B$3:$S$600,9,0) -> 04 | K3: =VLOOKUP($B3,master!$B$3:$S$600,11,0) -> RINGINHARJO | L3: =VLOOKUP($B3,master!$B$3:$S$600,12,0) -> BANTUL | M3: =VLOOKUP($B3,master!$B$3:$S$600,6,0) -> ALFI ANTORO | N3: =VLOOKUP($B3,master!$B$3:$S$600,15,0) -> SMP N 1BANTUL | O3: =VLOOKUP($B3,master!$B$3:$S$600,4,0) -> 26-02-2008
A4: 3 | B4: MSB24-03-556 | C4: 14288 | D4: ALAYKA SAFA | E4: =VLOOKUP(D4,Total!$C$2:$D$518,2,0) -> 11 RPL 1 | F4: =VLOOKUP(C4,Total!$B$2:$F$514,5,0) -> AKTIF | G4: =VLOOKUP($B4,master!$B$3:$S$600,16,0) -> 081393912565 | H4: =VLOOKUP($B4,master!$B$3:$S$600,17,0) -> 081393912565 | I4: =VLOOKUP($B4,master!$B$3:$S$600,8,0) -> DUKUH | J4: =VLOOKUP($B4,master!$B$3:$S$600,9,0) -> 2 | K4: =VLOOKUP($B4,master!$B$3:$S$600,11,0) -> GUWOSARI | L4: =VLOOKUP($B4,master!$B$3:$S$600,12,0) -> PAJANGAN | M4: =VLOOKUP($B4,master!$B$3:$S$600,6,0) -> ATIN KOMALASARI | N4: =VLOOKUP($B4,master!$B$3:$S$600,15,0) -> SMP N 3 PANDAK | O4: =VLOOKUP($B4,master!$B$3:$S$600,4,0) -> 27-03-2009
A5: 4 | B5: MSB24-03-462 | C5: 14289 | D5: ALERASYA BINTANG ADITYA | E5: =VLOOKUP(D5,Total!$C$2:$D$518,2,0) -> 11 RPL 1 | F5: =VLOOKUP(C5,Total!$B$2:$F$514,5,0) -> AKTIF | G5: =VLOOKUP($B5,master!$B$3:$S$600,16,0) -> 082136838721 | H5: =VLOOKUP($B5,master!$B$3:$S$600,17,0) -> 081393192003 | I5: =VLOOKUP($B5,master!$B$3:$S$600,8,0) -> PANGKAH | J5: =VLOOKUP($B5,master!$B$3:$S$600,9,0) -> 1 | K5: =VLOOKUP($B5,master!$B$3:$S$600,11,0) -> SUMBERAGUNG | L5: =VLOOKUP($B5,master!$B$3:$S$600,12,0) -> JETIS | M5: =VLOOKUP($B5,master!$B$3:$S$600,6,0) -> YULIA WULANDARI | N5: =VLOOKUP($B5,master!$B$3:$S$600,15,0) -> SMP N 3 JETIS | O5: =VLOOKUP($B5,master!$B$3:$S$600,4,0) -> 27-10-2007
A6: 5 | B6: MSB24-00-058 | C6: 14290 | D6: ALIF AZIZAN AMIRUDIN | E6: =VLOOKUP(D6,Total!$C$2:$D$518,2,0) -> 11 RPL 1 | F6: =VLOOKUP(C6,Total!$B$2:$F$514,5,0) -> AKTIF | G6: =VLOOKUP($B6,master!$B$3:$S$600,16,0) -> 08812469482 | H6: =VLOOKUP($B6,master!$B$3:$S$600,17,0) -> 0 | I6: =VLOOKUP($B6,master!$B$3:$S$600,8,0) -> JOPAITAN | J6: =VLOOKUP($B6,master!$B$3:$S$600,9,0) -> 2 | K6: =VLOOKUP($B6,master!$B$3:$S$600,11,0) -> SERUT | L6: =VLOOKUP($B6,master!$B$3:$S$600,12,0) -> PALBAPANG | M6: =VLOOKUP($B6,master!$B$3:$S$600,6,0) -> ENDANG WINARTI | N6: =VLOOKUP($B6,master!$B$3:$S$600,15,0) -> SMP MUHAMMADIYAH 2 BAMBANGLIPURO | O6: =VLOOKUP($B6,master!$B$3:$S$600,4,0) -> 19-02-2009
A7: 6 | B7: MSB24-03-576 | C7: 14291 | D7: ASHELIA REYVA SAFANA | E7: =VLOOKUP(D7,Total!$C$2:$D$518,2,0) -> 11 RPL 1 | F7: =VLOOKUP(C7,Total!$B$2:$F$514,5,0) -> AKTIF | G7: =VLOOKUP($B7,master!$B$3:$S$600,16,0) -> 087738471187 | H7: =VLOOKUP($B7,master!$B$3:$S$600,17,0) -> 085952895831 | I7: =VLOOKUP($B7,master!$B$3:$S$600,8,0) -> Sulang Lor | J7: =VLOOKUP($B7,master!$B$3:$S$600,9,0) -> 54 | K7: =VLOOKUP($B7,master!$B$3:$S$600,11,0) -> PATALAN | L7: =VLOOKUP($B7,master!$B$3:$S$600,12,0) -> JETIS | M7: =VLOOKUP($B7,master!$B$3:$S$600,6,0) -> Saifuddin | N7: =VLOOKUP($B7,master!$B$3:$S$600,15,0) -> SMP N 3 JETIS | O7: =VLOOKUP($B7,master!$B$3:$S$600,4,0) -> 23-03-2009
A8: 7 | B8: MSB24-03-310 | C8: 14292 | D8: AXEL SURYA PUTRA PRATAMA | E8: =VLOOKUP(D8,Total!$C$2:$D$518,2,0) -> 11 RPL 1 | F8: =VLOOKUP(C8,Total!$B$2:$F$514,5,0) -> AKTIF | G8: =VLOOKUP($B8,master!$B$3:$S$600,16,0) -> 0882008169635 | H8: =VLOOKUP($B8,master!$B$3:$S$600,17,0) -> 0882008169635 | I8: =VLOOKUP($B8,master!$B$3:$S$600,8,0) -> GUNTURAN | J8: =VLOOKUP($B8,master!$B$3:$S$600,9,0) -> 07 | K8: =VLOOKUP($B8,master!$B$3:$S$600,11,0) -> TRIHARJO | L8: =VLOOKUP($B8,master!$B$3:$S$600,12,0) -> PANDAK | M8: =VLOOKUP($B8,master!$B$3:$S$600,6,0) -> Sarjito | N8: =VLOOKUP($B8,master!$B$3:$S$600,15,0) -> SMP N 2 PANDAK | O8: =VLOOKUP($B8,master!$B$3:$S$600,4,0) -> 22-02-2009
A9: 8 | B9: MSB24-04-650 | C9: 14370 | D9: CHEREN DRUGEDI | E9: =VLOOKUP(D9,Total!$C$2:$D$518,2,0) -> 11 RPL 1 | F9: =VLOOKUP(C9,Total!$B$2:$F$514,5,0) -> KELUAR | G9: =VLOOKUP($B9,master!$B$3:$S$600,16,0) -> 085867413730 | H9: =VLOOKUP($B9,master!$B$3:$S$600,17,0) -> 082221364609 | I9: =VLOOKUP($B9,master!$B$3:$S$600,8,0) -> SIRAT | J9: =VLOOKUP($B9,master!$B$3:$S$600,9,0) -> 4 | K9: =VLOOKUP($B9,master!$B$3:$S$600,11,0) -> SIDOMULYO | L9: =VLOOKUP($B9,master!$B$3:$S$600,12,0) -> BAMBANGLIPURO | M9: =VLOOKUP($B9,master!$B$3:$S$600,6,0) -> SUPRIHATIN | N9: =VLOOKUP($B9,master!$B$3:$S$600,15,0) -> SMP N 1 BAMBANGLIPURO | O9: =VLOOKUP($B9,master!$B$3:$S$600,4,0) -> 7-11-2007
A10: 9 | B10: MSB24-03-511 | C10: 14293 | D10: CITRA ATHAYA SHYFA | E10: =VLOOKUP(D10,Total!$C$2:$D$518,2,0) -> 11 RPL 1 | F10: =VLOOKUP(C10,Total!$B$2:$F$514,5,0) -> AKTIF | G10: =VLOOKUP($B10,master!$B$3:$S$600,16,0) -> 081228148917 | H10: =VLOOKUP($B10,master!$B$3:$S$600,17,0) -> 085602727695 | I10: =VLOOKUP($B10,master!$B$3:$S$600,8,0) -> BAYURAN | J10: =VLOOKUP($B10,master!$B$3:$S$600,9,0) -> 4 | K10: =VLOOKUP($B10,master!$B$3:$S$600,11,0) -> SUMBERAGUNG | L10: =VLOOKUP($B10,master!$B$3:$S$600,12,0) -> JETIS | M10: =VLOOKUP($B10,master!$B$3:$S$600,6,0) -> MURGIYANTI | N10: =VLOOKUP($B10,master!$B$3:$S$600,15,0) -> SMP N 3 JETIS | O10: =VLOOKUP($B10,master!$B$3:$S$600,4,0) -> 15-06-2008
A11: 10 | B11: MSB24-03-586 | C11: 14294 | D11: DINDA SINTIASARI | E11: =VLOOKUP(D11,Total!$C$2:$D$518,2,0) -> 11 RPL 1 | F11: =VLOOKUP(C11,Total!$B$2:$F$514,5,0) -> AKTIF | G11: =VLOOKUP($B11,master!$B$3:$S$600,16,0) -> 0895421188596 | H11: =VLOOKUP($B11,master!$B$3:$S$600,17,0) -> 089506473141 | I11: =VLOOKUP($B11,master!$B$3:$S$600,8,0) -> TRAYEMAN | J11: =VLOOKUP($B11,master!$B$3:$S$600,9,0) -> 01 | K11: =VLOOKUP($B11,master!$B$3:$S$600,11,0) -> PLERET | L11: =VLOOKUP($B11,master!$B$3:$S$600,12,0) -> PLERET | M11: =VLOOKUP($B11,master!$B$3:$S$600,6,0) -> siti nariyah | N11: =VLOOKUP($B11,master!$B$3:$S$600,15,0) -> SMP N 2 PLERET | O11: =VLOOKUP($B11,master!$B$3:$S$600,4,0) -> 16-06-2008
A12: 11 | B12: MSB24-04-639 | C12: 14295 | D12: FACHRIANSYAH AL MA'RUF | E12: =VLOOKUP(D12,Total!$C$2:$D$518,2,0) -> 11 RPL 1 | F12: =VLOOKUP(C12,Total!$B$2:$F$514,5,0) -> AKTIF | G12: =VLOOKUP($B12,master!$B$3:$S$600,16,0) -> 0882005916840 | H12: =VLOOKUP($B12,master!$B$3:$S$600,17,0) -> 0895343008284 | I12: =VLOOKUP($B12,master!$B$3:$S$600,8,0) -> SENGGOTAN DK. DONGKE | J12: =VLOOKUP($B12,master!$B$3:$S$600,9,0) -> 009 | K12: =VLOOKUP($B12,master!$B$3:$S$600,11,0) -> TIRTONIRMOLO | L12: =VLOOKUP($B12,master!$B$3:$S$600,12,0) -> KASIHAN | M12: =VLOOKUP($B12,master!$B$3:$S$600,6,0) -> SUHARNO | N12: =VLOOKUP($B12,master!$B$3:$S$600,15,0) -> SMP MUHAMMADIYAH KASIHAN | O12: =VLOOKUP($B12,master!$B$3:$S$600,4,0) -> 8-08-2008
A13: 12 | B13: MSB24-03-596 | C13: 14296 | D13: FAISHAL HAFIZH RAMADHAN | E13: =VLOOKUP(D13,Total!$C$2:$D$518,2,0) -> 11 RPL 1 | F13: =VLOOKUP(C13,Total!$B$2:$F$514,5,0) -> AKTIF | G13: =VLOOKUP($B13,master!$B$3:$S$600,16,0) -> 085158898920 | H13: =VLOOKUP($B13,master!$B$3:$S$600,17,0) -> 081228682344 | I13: =VLOOKUP($B13,master!$B$3:$S$600,8,0) -> BEMBEM | J13: =VLOOKUP($B13,master!$B$3:$S$600,9,0) -> 8 | K13: =VLOOKUP($B13,master!$B$3:$S$600,11,0) -> TRIMULYO | L13: =VLOOKUP($B13,master!$B$3:$S$600,12,0) -> JETIS | M13: =VLOOKUP($B13,master!$B$3:$S$600,6,0) -> RUSDA FAUZAN | N13: =VLOOKUP($B13,master!$B$3:$S$600,15,0) -> SMP N 1 JETIS | O13: =VLOOKUP($B13,master!$B$3:$S$600,4,0) -> 27-09-2008
... A499: 498 | B499: MSB24-00-091 | C499: 13950 | D499: MUHAMMAD MUKLIS NURROHMAN | E499: =VLOOKUP(D499,Total!$C$2:$D$518,2,0) -> 11 TPM 2 | F499: =VLOOKUP(C499,Total!$B$2:$F$514,5,0) -> AKTIF | G499: =VLOOKUP($B499,master!$B$3:$S$600,16,0) -> 89652968104 | H499: =VLOOKUP($B499,master!$B$3:$S$600,17,0) -> 0 | I499: =VLOOKUP($B499,master!$B$3:$S$600,8,0) -> CENGKIRAN | J499: =VLOOKUP($B499,master!$B$3:$S$600,9,0) -> 8 | K499: =VLOOKUP($B499,master!$B$3:$S$600,11,0) -> TRIHARJO | L499: =VLOOKUP($B499,master!$B$3:$S$600,12,0) -> PANDAK | M499: =VLOOKUP($B499,master!$B$3:$S$600,6,0) -> ROHADI | N499: =VLOOKUP($B499,master!$B$3:$S$600,15,0) -> SMP N 3 PANDAK | O499: =VLOOKUP($B499,master!$B$3:$S$600,4,0) -> 10-06-2008
A500: 499 | B500: MSB24-00-122 | C500: 13951 | D500: MUHAMMAD NAUFAL RAMADHAN | E500: =VLOOKUP(D500,Total!$C$2:$D$518,2,0) -> 11 TPM 2 | F500: =VLOOKUP(C500,Total!$B$2:$F$514,5,0) -> AKTIF | G500: =VLOOKUP($B500,master!$B$3:$S$600,16,0) -> 082137188517 | H500: =VLOOKUP($B500,master!$B$3:$S$600,17,0) -> - | I500: =VLOOKUP($B498;master!$B$3:C511;8;0) | J500: =VLOOKUP($B500,master!$B$3:$S$600,9,0) -> 4 | K500: =VLOOKUP($B500,master!$B$3:$S$600,11,0) -> SRIHARDONO | L500: =VLOOKUP($B500,master!$B$3:$S$600,12,0) -> PUNDONG | M500: =VLOOKUP($B500,master!$B$3:$S$600,6,0) -> SAFRIDONI/WIJI LESTARI | N500: =VLOOKUP($B500,master!$B$3:$S$600,15,0) -> SMP Baitul Quran Cendekia | O500: =VLOOKUP($B500,master!$B$3:$S$600,4,0) -> 17-09-2007
A501: 500 | B501: MSB24-04-653 | C501: 14373 | D501: MUHAMMAD SYAHRUL IKHWAN | E501: =VLOOKUP(D501,Total!$C$2:$D$518,2,0) -> 11 TPM 2 | F501: =VLOOKUP(C501,Total!$B$2:$F$514,5,0) -> AKTIF | G501: =VLOOKUP($B501,master!$B$3:$S$600,16,0) -> 085643719786 | H501: =VLOOKUP($B501,master!$B$3:$S$600,17,0) -> 089692720008 | I501: =VLOOKUP($B501,master!$B$3:$S$600,8,0) -> BANDUNG | J501: =VLOOKUP($B501,master!$B$3:$S$600,9,0) -> 29 | K501: =VLOOKUP($B501,master!$B$3:$S$600,11,0) -> PENDOWOHARJO | L501: =VLOOKUP($B501,master!$B$3:$S$600,12,0) -> SEWON | M501: =VLOOKUP($B501,master!$B$3:$S$600,6,0) -> KUSWANTI | N501: =VLOOKUP($B501,master!$B$3:$S$600,15,0) -> SMP MUHAMMADIYAH SEWON | O501: =VLOOKUP($B501,master!$B$3:$S$600,4,0) -> 24-04-2008
A502: 501 | B502: MSB24-04-618 | C502: 13952 | D502: MUHAMMAD ZACKY BRIGAS SATRIAJI | E502: =VLOOKUP(D502,Total!$C$2:$D$518,2,0) -> 11 TPM 2 | F502: =VLOOKUP(C502,Total!$B$2:$F$514,5,0) -> AKTIF | G502: =VLOOKUP($B502,master!$B$3:$S$600,16,0) -> 089646568434 | H502: =VLOOKUP($B502,master!$B$3:$S$600,17,0) -> 0895620509933 | I502: =VLOOKUP($B502,master!$B$3:$S$600,8,0) -> PATEN | J502: =VLOOKUP($B502,master!$B$3:$S$600,9,0) -> 06 | K502: =VLOOKUP($B502,master!$B$3:$S$600,11,0) -> TIMBULHARJO | L502: =VLOOKUP($B502,master!$B$3:$S$600,12,0) -> SEWON | M502: =VLOOKUP($B502,master!$B$3:$S$600,6,0) -> ANDRIYANTO | N502: =VLOOKUP($B502,master!$B$3:$S$600,15,0) -> MTS N 4 BANTUL | O502: =VLOOKUP($B502,master!$B$3:$S$600,4,0) -> 26-03-2008
A503: 502 | B503: MSB24-02-248 | C503: 13953 | D503: NASYWAN HIDAYATULLAH | E503: =VLOOKUP(D503,Total!$C$2:$D$518,2,0) -> 11 TPM 2 | F503: =VLOOKUP(C503,Total!$B$2:$F$514,5,0) -> AKTIF | G503: =VLOOKUP($B503,master!$B$3:$S$600,16,0) -> 082230510426 | H503: =VLOOKUP($B503,master!$B$3:$S$600,17,0) -> 085967055628 | I503: =VLOOKUP($B503,master!$B$3:$S$600,8,0) -> SELOBENTAR | J503: =VLOOKUP($B503,master!$B$3:$S$600,9,0) -> 32 | K503: =VLOOKUP($B503,master!$B$3:$S$600,11,0) -> TRIMURTI | L503: =VLOOKUP($B503,master!$B$3:$S$600,12,0) -> SRANDAKAN | M503: =VLOOKUP($B503,master!$B$3:$S$600,6,0) -> RATIJAH | N503: =VLOOKUP($B503,master!$B$3:$S$600,15,0) -> SMP N 2 SRANDAKAN | O503: =VLOOKUP($B503,master!$B$3:$S$600,4,0) -> 27-11-2008
A504: 503 | B504: MSB24-00-113 | C504: 13954 | D504: NAUFAL PUTRA FIANTO | E504: =VLOOKUP(D504,Total!$C$2:$D$518,2,0) -> 11 TPM 2 | F504: =VLOOKUP(C504,Total!$B$2:$F$514,5,0) -> AKTIF | G504: =VLOOKUP($B504,master!$B$3:$S$600,16,0) -> 081804388666 | H504: =VLOOKUP($B504,master!$B$3:$S$600,17,0) -> - | I504: =VLOOKUP($B504,master!$B$3:$S$600,8,0) -> GENDENG | J504: =VLOOKUP($B504,master!$B$3:$S$600,9,0) -> 3 | K504: =VLOOKUP($B504,master!$B$3:$S$600,11,0) -> BANGUNJIWO | L504: =VLOOKUP($B504,master!$B$3:$S$600,12,0) -> KASIHAN | M504: =VLOOKUP($B504,master!$B$3:$S$600,6,0) -> SUWANTO | N504: =VLOOKUP($B504,master!$B$3:$S$600,15,0) -> MTS MUHAMMADIYAH KASIHAN | O504: =VLOOKUP($B504,master!$B$3:$S$600,4,0) -> 9-10-2008
A505: 504 | B505: MSB24-04-638 | C505: 13955 | D505: NICO DANI ANGGARA | E505: =VLOOKUP(D505,Total!$C$2:$D$518,2,0) -> 11 TPM 2 | F505: =VLOOKUP(C505,Total!$B$2:$F$514,5,0) -> AKTIF | G505: =VLOOKUP($B505,master!$B$3:$S$600,16,0) -> 082265269142 | H505: =VLOOKUP($B505,master!$B$3:$S$600,17,0) -> 083841783198 | I505: =VLOOKUP($B505,master!$B$3:$S$600,8,0) -> BARAN | J505: =VLOOKUP($B505,master!$B$3:$S$600,9,0) -> 001 | K505: =VLOOKUP($B505,master!$B$3:$S$600,11,0) -> SRIHARDONO | L505: =VLOOKUP($B505,master!$B$3:$S$600,12,0) -> PUNDONG | M505: =VLOOKUP($B505,master!$B$3:$S$600,6,0) -> AGUS SARWANTO | N505: =VLOOKUP($B505,master!$B$3:$S$600,15,0) -> SMP N 2 PUNDONG | O505: =VLOOKUP($B505,master!$B$3:$S$600,4,0) -> 29-03-2008
A506: 505 | B506: MSB24-03-385 | C506: 13956 | D506: NUR AZIZ RAMADHANI | E506: =VLOOKUP(D506,Total!$C$2:$D$518,2,0) -> 11 TPM 2 | F506: =VLOOKUP(C506,Total!$B$2:$F$514,5,0) -> AKTIF | G506: =VLOOKUP($B506,master!$B$3:$S$600,16,0) -> 089632313761/089636391551 | H506: =VLOOKUP($B506,master!$B$3:$S$600,17,0) -> 08963639155 | I506: =VLOOKUP($B506,master!$B$3:$S$600,8,0) -> TEGAL DOWO | J506: =VLOOKUP($B506,master!$B$3:$S$600,9,0) -> 4 | K506: =VLOOKUP($B506,master!$B$3:$S$600,11,0) -> BANTUL | L506: =VLOOKUP($B506,master!$B$3:$S$600,12,0) -> BANTUL | M506: =VLOOKUP($B506,master!$B$3:$S$600,6,0) -> KARWATI | N506: =VLOOKUP($B506,master!$B$3:$S$600,15,0) -> SMP N 4 SEWON | O506: =VLOOKUP($B506,master!$B$3:$S$600,4,0) -> 1-10-2007
A507: 506 | B507: MSB24-03-484 | C507: 13957 | D507: RAFI SATRIA ATMAJA | E507: =VLOOKUP(D507,Total!$C$2:$D$518,2,0) -> 11 TPM 2 | F507: =VLOOKUP(C507,Total!$B$2:$F$514,5,0) -> AKTIF | G507: =VLOOKUP($B507,master!$B$3:$S$600,16,0) -> 085103536350 | H507: =VLOOKUP($B507,master!$B$3:$S$600,17,0) -> 0882006985378 | I507: =VLOOKUP($B507,master!$B$3:$S$600,8,0) -> SINGOSAREN | J507: =VLOOKUP($B507,master!$B$3:$S$600,9,0) -> 1 | K507: =VLOOKUP($B507,master!$B$3:$S$600,11,0) -> WUKIRSARI | L507: =VLOOKUP($B507,master!$B$3:$S$600,12,0) -> IMOGIRI | M507: =VLOOKUP($B507,master!$B$3:$S$600,6,0) -> MUHAMAD SUBKHAN | N507: =VLOOKUP($B507,master!$B$3:$S$600,15,0) -> SMP AL MA'ARIF IMOGIRI | O507: =VLOOKUP($B507,master!$B$3:$S$600,4,0) -> 7-08-2008
A508: 507 | B508: MSB24-00-061 | C508: 13958 | D508: RESANG PANGESTU | E508: =VLOOKUP(D508,Total!$C$2:$D$518,2,0) -> 11 TPM 2 | F508: =VLOOKUP(C508,Total!$B$2:$F$514,5,0) -> AKTIF | G508: =VLOOKUP($B508,master!$B$3:$S$600,16,0) -> 85228636179 | H508: =VLOOKUP($B508,master!$B$3:$S$600,17,0) -> 0 | I508: =VLOOKUP($B508,master!$B$3:$S$600,8,0) -> KADISORO | J508: =VLOOKUP($B508,master!$B$3:$S$600,9,0) -> 3 | K508: =VLOOKUP($B508,master!$B$3:$S$600,11,0) -> GILANGHARJO | L508: =VLOOKUP($B508,master!$B$3:$S$600,12,0) -> PANDAK | M508: =VLOOKUP($B508,master!$B$3:$S$600,6,0) -> ANGGA INDRIAWAN P | N508: =VLOOKUP($B508,master!$B$3:$S$600,15,0) -> SMP N 3 PANDAK | O508: =VLOOKUP($B508,master!$B$3:$S$600,4,0) -> 2-02-2008
A509: 508 | B509: MSB24-00-111 | C509: 13959 | D509: REZALDY YUGA PUTRA | E509: =VLOOKUP(D509,Total!$C$2:$D$518,2,0) -> 11 TPM 2 | F509: =VLOOKUP(C509,Total!$B$2:$F$514,5,0) -> AKTIF | G509: =VLOOKUP($B509,master!$B$3:$S$600,16,0) -> 088216647137 | H509: =VLOOKUP($B509,master!$B$3:$S$600,17,0) -> - | I509: =VLOOKUP($B509,master!$B$3:$S$600,8,0) -> NENGAHAN | J509: =VLOOKUP($B509,master!$B$3:$S$600,9,0) -> 86 | K509: =VLOOKUP($B509,master!$B$3:$S$600,11,0) -> TRIMURTI | L509: =VLOOKUP($B509,master!$B$3:$S$600,12,0) -> SRANDAKAN | M509: =VLOOKUP($B509,master!$B$3:$S$600,6,0) -> ISMUNANDAR | N509: =VLOOKUP($B509,master!$B$3:$S$600,15,0) -> SMP N 1 SRANDAKAN | O509: =VLOOKUP($B509,master!$B$3:$S$600,4,0) -> 17-02-2009
A510: 509 | B510: MSB24-04-607 | C510: 13960 | D510: RIFKI ADINATA | E510: =VLOOKUP(D510,Total!$C$2:$D$518,2,0) -> 11 TPM 2 | F510: =VLOOKUP(C510,Total!$B$2:$F$514,5,0) -> AKTIF | G510: =VLOOKUP($B510,master!$B$3:$S$600,16,0) -> 083126193252 | H510: =VLOOKUP($B510,master!$B$3:$S$600,17,0) -> 083126193252 | I510: =VLOOKUP($B510,master!$B$3:$S$600,8,0) -> LANTENG 2 | J510: =VLOOKUP($B510,master!$B$3:$S$600,9,0) -> 4 | K510: =VLOOKUP($B510,master!$B$3:$S$600,11,0) -> SELOPAMIORO | L510: =VLOOKUP($B510,master!$B$3:$S$600,12,0) -> IMOGIRI | M510: =VLOOKUP($B510,master!$B$3:$S$600,6,0) -> MURSIDI | N510: =VLOOKUP($B510,master!$B$3:$S$600,15,0) -> SMP N 3 IMOGIRI | O510: =VLOOKUP($B510,master!$B$3:$S$600,4,0) -> 29-08-2008
A511: 510 | B511: MSB24-01-198 | C511: 13961 | D511: RIZKY ADI SAPUTRA | E511: =VLOOKUP(D511,Total!$C$2:$D$518,2,0) -> 11 TPM 2 | F511: =VLOOKUP(C511,Total!$B$2:$F$514,5,0) -> AKTIF | G511: =VLOOKUP($B511,master!$B$3:$S$600,16,0) -> 085927487315 | H511: =VLOOKUP($B511,master!$B$3:$S$600,17,0) -> 082326059380 | I511: =VLOOKUP($B511,master!$B$3:$S$600,8,0) -> SUKORAME | J511: =VLOOKUP($B511,master!$B$3:$S$600,9,0) -> 020 | K511: =VLOOKUP($B511,master!$B$3:$S$600,11,0) -> MANGUNAN | L511: =VLOOKUP($B511,master!$B$3:$S$600,12,0) -> DLINGO | M511: =VLOOKUP($B511,master!$B$3:$S$600,6,0) -> Slamet widodo | N511: =VLOOKUP($B511,master!$B$3:$S$600,15,0) -> SMP Muhammadiyah 2 Dlingo | O511: =VLOOKUP($B511,master!$B$3:$S$600,4,0) -> 7-12-2008
A512: 511 | B512: MSB24-03-526 | C512: 13962 | D512: SILVARIO RIZKI RAMADHANI | E512: =VLOOKUP(D512,Total!$C$2:$D$518,2,0) -> 11 TPM 2 | F512: =VLOOKUP(C512,Total!$B$2:$F$514,5,0) -> AKTIF | G512: =VLOOKUP($B512,master!$B$3:$S$600,16,0) -> 088980738038 | H512: =VLOOKUP($B512,master!$B$3:$S$600,17,0) -> 0882005858497 | I512: =VLOOKUP($B512,master!$B$3:$S$600,8,0) -> BULU | J512: =VLOOKUP($B512,master!$B$3:$S$600,9,0) -> 2 | K512: =VLOOKUP($B512,master!$B$3:$S$600,11,0) -> TRIMULYO | L512: =VLOOKUP($B512,master!$B$3:$S$600,12,0) -> JETIS | M512: =VLOOKUP($B512,master!$B$3:$S$600,6,0) -> YUNIATI | N512: =VLOOKUP($B512,master!$B$3:$S$600,15,0) -> SMP MUHAMMADIYAH IMOGIRI | O512: =VLOOKUP($B512,master!$B$3:$S$600,4,0) -> 25-09-2008
... A514: 513 | B514: MSB24-00-105 | C514: 13964 | D514: YUNUZ | E514: =VLOOKUP(D514,Total!$C$2:$D$518,2,0) -> 11 TPM 2 | F514: =VLOOKUP(C514,Total!$B$2:$F$514,5,0) -> AKTIF | G514: =VLOOKUP($B514,master!$B$3:$S$600,16,0) -> 082221149233 | H514: =VLOOKUP($B514,master!$B$3:$S$600,17,0) -> - | I514: =VLOOKUP($B514,master!$B$3:$S$600,8,0) -> KLEGEN | J514: =VLOOKUP($B514,master!$B$3:$S$600,9,0) -> 2 | K514: =VLOOKUP($B514,master!$B$3:$S$600,11,0) -> TIRTOSARI | L514: =VLOOKUP($B514,master!$B$3:$S$600,12,0) -> KRETEK | M514: =VLOOKUP($B514,master!$B$3:$S$600,6,0) -> HADI MARWANTA | N514: =VLOOKUP($B514,master!$B$3:$S$600,15,0) -> SMP N 1 KRETEK | O514: =VLOOKUP($B514,master!$B$3:$S$600,4,0) -> 16-04-2008

Sheet master
A1: No | B1: Nomor Pendaftaran | C1: Nama Lengkap | D1: Tempat Lahir | E1: Tangal Lahir Siswa | F1: JeKel | G1: Nama Ortu | H1: Pekerjaan Ortu | I1: Dusun | J1: RT | K1: RW | L1: Kelurahan | M1: Kecamatan | N1: Kabupaten | O1: Prov | P1: Asal Sekolah | Q1: No Siswa | R1: No Ortu | S1: Pil 1
A2: a0 | B2: a1 | C2: a2 | D2: a3 | E2: a4 | F2: a5 | G2: a6 | H2: a7 | I2: a8 | J2: a9 | K2: a10 | L2: a11 | M2: a12 | N2: a13 | O2: a14 | P2: a15 | Q2: a16 | R2: a17 | S2: a18
A3: 1 | B3: MSB24-00-001 | C3: ADITYA DWI CAHYANTO | D3: BANTUL | E3: 123456-123456-admin | G3: WIYANTO | H3: ASN | I3: NITIPRAYAN | J3: 3 | K3: 0 | L3: NGESTIHARJO | M3: KASIHAN | N3: BANTUL | O3: DIY | P3: SMP MUHAMMADIYAH KASIHAN | Q3: 81391810007 | R3: 0 | S3: 12345
A4: 2 | B4: MSB24-00-002 | C4: ALFIAN CAHYA PRATAMA | D4: BANTUL | E4: 7-03-2008 | F4: L | G4: HERU SUSILO | H4: BURUH | I4: BAJANG | J4: 1 | K4: 0 | L4: WIJIREJO | M4: PANDAK | N4: BANTUL | O4: DIY | P4: SMP AL-ISLAM KARTASURA | Q4: 87817742974 | R4: 0 | S4: TBSM
A5: 3 | B5: MSB24-00-003 | C5: ANDIKA DWI KURNIAWAN | D5: BANTUL | E5: 28-05-2008 | F5: L | G5: SUBEKTI | H5: WIRASWASTA | I5: KEPEK | J5: 5 | K5: 0 | L5: TIMBULHARJO | M5: SEWON | N5: BANTUL | O5: DIY | P5: MTS N 2 BANTUL | Q5: 088221260292 | R5: 0 | S5: TBSM
A6: 4 | B6: MSB24-00-004 | C6: ILHAM EKA PUTRA ANNAFI | D6: BANTUL | E6: 24-09-2008 | F6: L | G6: PARJILAN | H6: KARYAWAN SWASTA | I6: JAYAN | J6: 2 | K6: 0 | L6: CANDEN | M6: JETIS | N6: BANTUL | O6: DIY | P6: SMP N 3 JETIS | Q6: 82221022299 | R6: 0 | S6: TKR
A7: 5 | B7: MSB24-00-005 | C7: MUHAMMAD DZAKY AMAR FAUZAN | D7: BANTUL | E7: 13-05-2008 | F7: L | G7: ADHI PRASTOWO | H7: BURUH | I7: PEPE | J7: 4 | K7: 0 | L7: TRIRENGGO | M7: BANTUL | N7: BANTUL | O7: DIY | P7: SMP N 1 BANTUL | Q7: 87700043003 | R7: 0 | S7: TKR
A8: 6 | B8: MSB24-00-006 | C8: REVAL REZKY RAMADHAN | D8: BANTUL | E8: 19-09-2008 | F8: L | G8: IVAN PAMUNGKAS | H8: BURUH | I8: PEPE | J8: 5 | K8: 0 | L8: TRIRENGGO | M8: BANTUL | N8: BANTUL | O8: DIY | P8: SMP N 1 BANTUL | Q8: 083867945082 | R8: 0 | S8: TKR
